Workbook

Sheet 1.Quy trình
A1: QUY TRÌNH XỬ LÝ GIÁ SAU TIẾP NHẬN ĐƠN HÀNG NHÀ MÁY DEGO
A3: TỔNG QUAN
A4: Tiếp nhận đơn → Kiểm tra mã → Kiểm tra giá → Tính giá → Kiểm soát → Duyệt → Cập nhật hệ thống
A6: STT | B6: Công đoạn | C6: Nội dung thực hiện | D6: Kết quả | E6: Trách nhiệm | F6: Biểu mẫu | G6: Ghi chú | H6: Hình minh hoạ 1 | I6: Hình minh hoạ 2 | J6: Hình minh hoạ 3
A7: 1 | B7: Tiếp nhận đơn | C7: 1. Điều phối tiếp nhận đơn hàng KD vào drive "SX-ĐIỀU PHỐI THÀNH PHẨM" sheet "ĐIỀU PHỐI" | D7: Đơn hàng được ghi nhận đầy đủ, chính xác Làm cơ sở dữ liệu đầu vào cho toàn bộ quy trình | E7: KD-> Điều phối | F7: SX-ĐIỀU PHỐI THÀNH PHẨM | G7: Hình minh hoạ 1: ĐIỀU PHỐI
A8: 2 | B8: Thực hiện kiểm tra đơn hàng | C8: 1. Vào dvire "SX-ĐIỀU PHỐI THÀNH PHẨM" vào sheet" ĐIỀU PHỐI" chọn (cột B) NCC đề xuất lọc NCC Dego Cần Thơ. | D8: Hiển thị các đơn hàng cần kiểm tra giá. | E8: Nhà máy | F8: SX-ĐIỀU PHỐI THÀNH PHẨM | G8: Hình minh hoạ 1: ĐIỀU PHỐI Hình minh hoạ 2: HÀNG NGÀY 2026
C9: 2. Kiểm tra từng đơn hàng: Thương hiệu, Mã hàng, Tên pháp lý, Công thức, Giá bán khách hàng,… → Nếu thiếu thông tin, yêu cầu bổ sung ngay trước khi xử lý tiếp. Bắt buộc cập nhật: Mã công thức → Đảm bảo sử dụng đúng công thức, tránh sai giá (do cùng công thức nhưng mỗi thương hiệu có giá khác nhau). Giá bán khách hàng → Trường hợp không cung cấp giá bán, nếu phát sinh âm biên lợi nhuận thì BPYC tự chịu trách nhiệm. | D9: Dữ liệu đơn hàng đầy đủ, chính xác Đủ điều kiện để tính giá, hạn chế sai và âm lợi nhuận
C10: 3. Cập nhật đơn hàng vào sheet “2. HÀNG NGÀY 2026” (Drive “CẬP NHẬT ĐƠN HÀNG HẰNG NGÀY”) → Kiểm tra công thức từ sheet “ĐIỀU PHỐI” → Copy dữ liệu từ cột B đến cột Q và dán vào file theo dõi | D10: Đơn hàng được cập nhật đầy đủ, đúng công thức Dữ liệu đồng bộ, sẵn sàng cho bước tính giá → Tiến hành so sánh và kiểm tra lại công thức của đơn hàng đã cập nhật.
A11: 3 | B11: Kiểm tra trạng thái công thức | C11: B1. Lấy mã công thức (cột K) theo đơn hàng trên sheet “ĐIỀU PHỐI” của Drive "SX-ĐIỀU PHỐI THÀNH PHẨM" | D11: Xác định rõ công thức đã có hay chưa Cập nhật trạng thái xử lý Đảm bảo đơn hàng được xử lý đúng tiến độ | E11: Nhà máy, Lab | F11: SX-ĐIỀU PHỐI THÀNH PHẨM
C12: B2. Vào Drive “Giá BTP PB bàn giao Nhà máy” → mở sheet “11. DANH SÁCH MÃ HÀNG GẮN VỚI CTPB KD” | F12: Drive Giá BTP PB bàn giao Nhà máy
C13: B3. Kiểm tra công thức theo mã hàng / mã công thức: Trường hợp 1: Công thức cũ (đã có giá BTP) → Copy công thức cũ vào cột R sheet “2. HÀNG NGÀY 2026” (để theo dõi, kiểm soát sai/đổi công thức) → Cập nhật trạng thái cột BE (Xử lý giá vốn Hương): “Đã có giá, chờ Lab phản hồi” trên drive "SX-ĐIỀU PHỐI THÀNH PHẨM" Trường hợp 2: Công thức mới (chưa có giá) → Gửi mã công thức + đơn hàng vào nhóm Zalo “SX – CẬP NHẬT LINK BDM MẪU” cho Lab → Cập nhật trạng thái cột BE: “Chưa có công thức lab” Trên drive "SX-ĐIỀU PHỐI THÀNH PHẨM" → Chờ Lab xử lý: - Lab cập nhật mã công thức và giá vốn.. - Gửi giá vốn cho KD -> đợi KD xác nhận giá → cho đi đơn hàng/huỷ đơn/tạm ngưng. | F13: Drive Giá BTP PB bàn giao Nhà máy
C14: B4. Chờ Lab kiểm tra đơn hàng tại sheet “4.DEGO CẦN THƠ” | F14: CẬP NHẬT ĐƠN HÀNG PHÁT SINH HÀNG NGÀY
C15: B5. Lab cập nhật công thức theo dơn hàng vào sheet “3. Công thức lab theo từng mã hàng” → Theo dõi tiến độ để đảm bảo đơn hàng xử lý đúng hạn. | F15: CẬP NHẬT ĐƠN HÀNG PHÁT SINH HÀNG NGÀY
A16: 4 | B16: Xử lý giá | C16: Vào Drive “Giá BTP PB bàn giao Nhà máy” → sheet “11. DANH SÁCH MÃ HÀNG GẮN VỚI CTPB KD” để xử lý giá: | D16: Mỗi đơn hàng được xử lý đúng theo từng trường hợp Đảm bảo kiểm soát giá, tránh sai và hạn chế âm lợi nhuận | E16: Nhà máy, Lab | F16: Drive Giá BTP PB bàn giao Nhà máy
C17: Trường hợp 1: Mã cũ – công thức cũ → Kiểm tra mã hàng và giá bán khách hàng 1. Giá bán không đổi → Duyệt giá, cho đi đơn 2. Giá bán tăng → Vẫn cho đi đơn 3. Giá bán giảm → Thông báo KD xác nhận: - Đồng ý → Đi đơn - Không đồng ý →Đợi KD phản hồi lại giá hoặc huỷ đơn hàng theo yêu cầu của KD → Cập nhật lại thông tin vào Drive
C18: Trường hợp 2: Mã cũ – công thức mới → Kiểm tra thông tin KD đã nhập. Nếu KD nhập sai → Yêu cầu KD chỉnh sửa lại. Nếu đúng và đã xác nhận có cải tiến công thức: → Thực hiện quy trình hỏi công thức và giá Lab → Sau khi lab phản hồi: - Có giá vốn -> báo giá cho KD 1. xác nhận → Duyệt, cho đi đơn 2. chưa xác nhận → Tạm ngưng hoặc hủy đơn
C19: Trường hợp 3: Mã mới – công thức mới → Thực hiện quy trình hỏi công thức và giá mẫu Lab → Sau khi có giá: - Có giá vốn -> báo giá cho KD 1. xác nhận → Duyệt, cho đi đơn 2. chưa xác nhận → Tạm ngưng hoặc hủy đơn
A20: 5 | B20: Xác nhận và theo dõi đơn hàng | C20: Hoàn tất các bước kiểm tra giá: vào drive " SX-ĐIỀU PHỐI THÀNH PHẨM" sheet "Điều phối" - Cập nhật trạng thái phù hợp với từng đơn hàng tại cột BF (Xử lý giá vốn Hương): Đã xử lý giá Chưa có công thức lab Đã có giá, chờ Lab phản hồi Chưa có thông tin công thức đơn hàng từ KD KD huỷ đơn Kèm theo ghi chú chi tiết vào cột BG (Ghi chú) | D20: Trạng thái đơn hàng được cập nhật rõ ràng Dễ theo dõi và kiểm soát tiến độ xử lý | E20: Nhà máy | F20: SX-ĐIỀU PHỐI THÀNH PHẨM | G20: Hình minh hoạ 1: ĐIỀU PHỐI duyệt giá cho đi đơn hàng

Sheet 3. Công thức lab theo từng mã h
A2: =IFERROR(__xludf.DUMMYFUNCTION("IMPORTRANGE(""https://docs.google.com/spreadsheets/d/1JLA1lPRqgRUG4HROAt93tplO_kWfItwG1V1S9I1AmOc/edit?gid=312821278#gid=312821278"",""DATA LIÊN KẾT MÃ CT - MÃ HÀNG!A2:R"")"),"Công thức") -> Công thức | B2: =IFERROR(__xludf.DUMMYFUNCTION("""COMPUTED_VALUE"""),"Công thức") -> Công thức | C2: =IFERROR(__xludf.DUMMYFUNCTION("""COMPUTED_VALUE"""),"Công thức") -> Công thức | D2: =IFERROR(__xludf.DUMMYFUNCTION("""COMPUTED_VALUE"""),"Click chọn") -> Click chọn | E2: =IFERROR(__xludf.DUMMYFUNCTION("""COMPUTED_VALUE"""),"Công thức") -> Công thức | F2: =IFERROR(__xludf.DUMMYFUNCTION("""COMPUTED_VALUE"""),"Nhập") -> Nhập | G2: =IFERROR(__xludf.DUMMYFUNCTION("""COMPUTED_VALUE"""),"Công thức") -> Công thức | H2: =IFERROR(__xludf.DUMMYFUNCTION("""COMPUTED_VALUE"""),"Công thức") -> Công thức | I2: =IFERROR(__xludf.DUMMYFUNCTION("""COMPUTED_VALUE"""),"Công thức") -> Công thức | J2: =IFERROR(__xludf.DUMMYFUNCTION("""COMPUTED_VALUE"""),"Công thức") -> Công thức | K2: =IFERROR(__xludf.DUMMYFUNCTION("""COMPUTED_VALUE"""),"Công thức") -> Công thức | L2: =IFERROR(__xludf.DUMMYFUNCTION("""COMPUTED_VALUE"""),"Công thức") -> Công thức | M2: =IFERROR(__xludf.DUMMYFUNCTION("""COMPUTED_VALUE"""),"Công thức") -> Công thức | N2: =IFERROR(__xludf.DUMMYFUNCTION("""COMPUTED_VALUE"""),"Click chọn") -> Click chọn | O2: =IFERROR(__xludf.DUMMYFUNCTION("""COMPUTED_VALUE"""),"Công thức") -> Công thức | P2: =IFERROR(__xludf.DUMMYFUNCTION("""COMPUTED_VALUE"""),"Công thức") -> Công thức | Q2: =IFERROR(__xludf.DUMMYFUNCTION("""COMPUTED_VALUE"""),"Công thức") -> Công thức | R2: =IFERROR(__xludf.DUMMYFUNCTION("""COMPUTED_VALUE"""),"Nhập") -> Nhập
A3: =IFERROR(__xludf.DUMMYFUNCTION("""COMPUTED_VALUE"""),"STT") -> STT | B3: =IFERROR(__xludf.DUMMYFUNCTION("""COMPUTED_VALUE"""),"Ngày nhập BĐM") -> Ngày nhập BĐM | C3: =IFERROR(__xludf.DUMMYFUNCTION("""COMPUTED_VALUE"""),"Số lần cập nhật CT cho HH") -> Số lần cập nhật CT cho HH | D3: =IFERROR(__xludf.DUMMYFUNCTION("""COMPUTED_VALUE"""),"Phân loại") -> Phân loại | E3: =IFERROR(__xludf.DUMMYFUNCTION("""COMPUTED_VALUE"""),"Ngày yêu cầu (KD)") -> Ngày yêu cầu (KD) | F3: =IFERROR(__xludf.DUMMYFUNCTION("""COMPUTED_VALUE"""),"Mã đơn đặt hàng (KD)") -> Mã đơn đặt hàng (KD) | G3: =IFERROR(__xludf.DUMMYFUNCTION("""COMPUTED_VALUE"""),"Mã HH (KD)") -> Mã HH (KD) | H3: =IFERROR(__xludf.DUMMYFUNCTION("""COMPUTED_VALUE"""),"Tên sản phẩm (KD)") -> Tên sản phẩm (KD) | I3: =IFERROR(__xludf.DUMMYFUNCTION("""COMPUTED_VALUE"""),"CTPL (KD)") -> CTPL (KD) | J3: =IFERROR(__xludf.DUMMYFUNCTION("""COMPUTED_VALUE"""),"Mã CT KD yêu cầu (KD)") -> Mã CT KD yêu cầu (KD) | K3: =IFERROR(__xludf.DUMMYFUNCTION("""COMPUTED_VALUE"""),"Ngày yêu cầu sẵn kho (KD)") -> Ngày yêu cầu sẵn kho (KD) | L3: =IFERROR(__xludf.DUMMYFUNCTION("""COMPUTED_VALUE"""),"Mã yêu cầu (LAB)") -> Mã yêu cầu (LAB) | M3: =IFERROR(__xludf.DUMMYFUNCTION("""COMPUTED_VALUE"""),"Tên mẫu (LAB)") -> Tên mẫu (LAB) | N3: =IFERROR(__xludf.DUMMYFUNCTION("""COMPUTED_VALUE"""),"Mã công thức (LAB)") -> Mã công thức (LAB) | O3: =IFERROR(__xludf.DUMMYFUNCTION("""COMPUTED_VALUE"""),"CTPL (LAB)") -> CTPL (LAB) | P3: =IFERROR(__xludf.DUMMYFUNCTION("""COMPUTED_VALUE"""),"CTPL (KD)") -> CTPL (KD) | Q3: =IFERROR(__xludf.DUMMYFUNCTION("""COMPUTED_VALUE"""),"Kiểm tra pháp lý (O:P)") -> Kiểm tra pháp lý (O:P) | R3: =IFERROR(__xludf.DUMMYFUNCTION("""COMPUTED_VALUE"""),"Tiến độ xử lý công thức (nguyên nhân chưa có công thức, thời gian dự kiến có công thức") -> Tiến độ xử lý công thức (nguyên nhân chưa có công thức, thời gian dự kiến có công thức
A4: =IFERROR(__xludf.DUMMYFUNCTION("""COMPUTED_VALUE"""),1.0) -> 1 | B4: =IFERROR(__xludf.DUMMYFUNCTION("""COMPUTED_VALUE"""),45885.0) -> 45885 | C4: =IFERROR(__xludf.DUMMYFUNCTION("""COMPUTED_VALUE"""),1.0) -> 1 | D4: =IFERROR(__xludf.DUMMYFUNCTION("""COMPUTED_VALUE"""),"CT MỚI") -> CT MỚI | G4: =IFERROR(__xludf.DUMMYFUNCTION("""COMPUTED_VALUE"""),"HH3887") -> HH3887 | H4: =IFERROR(__xludf.DUMMYFUNCTION("""COMPUTED_VALUE"""),"IDA Global - I - 3887 - VG RICE 01 - 500ml - 40") -> IDA Global - I - 3887 - VG RICE 01 - 500ml - 40 | I4: =IFERROR(__xludf.DUMMYFUNCTION("""COMPUTED_VALUE"""),"#N/A") -> #N/A | L4: =IFERROR(__xludf.DUMMYFUNCTION("""COMPUTED_VALUE"""),"I01180225-01") -> I01180225-01 | M4: =IFERROR(__xludf.DUMMYFUNCTION("""COMPUTED_VALUE"""),"VG RICE 01") -> VG RICE 01 | N4: =IFERROR(__xludf.DUMMYFUNCTION("""COMPUTED_VALUE"""),"13XL0014") -> 13XL0014 | O4: =IFERROR(__xludf.DUMMYFUNCTION("""COMPUTED_VALUE"""),"Phân bón Vi lượng AGAMA-SUPPORT") -> Phân bón Vi lượng AGAMA-SUPPORT | P4: =IFERROR(__xludf.DUMMYFUNCTION("""COMPUTED_VALUE"""),"#N/A") -> #N/A | Q4: =IFERROR(__xludf.DUMMYFUNCTION("""COMPUTED_VALUE"""),"KHÔNG KHỚP") -> KHÔNG KHỚP
A5: =IFERROR(__xludf.DUMMYFUNCTION("""COMPUTED_VALUE"""),2.0) -> 2 | B5: =IFERROR(__xludf.DUMMYFUNCTION("""COMPUTED_VALUE"""),45890.0) -> 45890 | C5: =IFERROR(__xludf.DUMMYFUNCTION("""COMPUTED_VALUE"""),1.0) -> 1 | D5: =IFERROR(__xludf.DUMMYFUNCTION("""COMPUTED_VALUE"""),"CT MỚI") -> CT MỚI | G5: =IFERROR(__xludf.DUMMYFUNCTION("""COMPUTED_VALUE"""),"HH3924") -> HH3924 | H5: =IFERROR(__xludf.DUMMYFUNCTION("""COMPUTED_VALUE"""),"BAMBOO MG KẼM") -> BAMBOO MG KẼM | I5: =IFERROR(__xludf.DUMMYFUNCTION("""COMPUTED_VALUE"""),"#N/A") -> #N/A | L5: =IFERROR(__xludf.DUMMYFUNCTION("""COMPUTED_VALUE"""),"BB26040725") -> BB26040725 | M5: =IFERROR(__xludf.DUMMYFUNCTION("""COMPUTED_VALUE"""),"BAMBOO MG KẼM LOTUS DIỆP LỤC") -> BAMBOO MG KẼM LOTUS DIỆP LỤC | N5: =IFERROR(__xludf.DUMMYFUNCTION("""COMPUTED_VALUE"""),"13XL0017") -> 13XL0017 | O5: =IFERROR(__xludf.DUMMYFUNCTION("""COMPUTED_VALUE"""),"Phân bón vi lượng Phú Sĩ FJ-09 Kẽm Mg") -> Phân bón vi lượng Phú Sĩ FJ-09 Kẽm Mg | P5: =IFERROR(__xludf.DUMMYFUNCTION("""COMPUTED_VALUE"""),"#N/A") -> #N/A | Q5: =IFERROR(__xludf.DUMMYFUNCTION("""COMPUTED_VALUE"""),"KHÔNG KHỚP") -> KHÔNG KHỚP
A6: =IFERROR(__xludf.DUMMYFUNCTION("""COMPUTED_VALUE"""),3.0) -> 3 | B6: =IFERROR(__xludf.DUMMYFUNCTION("""COMPUTED_VALUE"""),45890.0) -> 45890 | C6: =IFERROR(__xludf.DUMMYFUNCTION("""COMPUTED_VALUE"""),1.0) -> 1 | D6: =IFERROR(__xludf.DUMMYFUNCTION("""COMPUTED_VALUE"""),"CT MỚI") -> CT MỚI | G6: =IFERROR(__xludf.DUMMYFUNCTION("""COMPUTED_VALUE"""),"HH3933") -> HH3933 | H6: =IFERROR(__xludf.DUMMYFUNCTION("""COMPUTED_VALUE"""),"LOTUS AGROCHEM - VII - 3933 - LOTUS DIỆP LỤC (Nước trắng sữa) - 500ml - 40") -> LOTUS AGROCHEM - VII - 3933 - LOTUS DIỆP LỤC (Nước trắng sữa) - 500ml - 40 | I6: =IFERROR(__xludf.DUMMYFUNCTION("""COMPUTED_VALUE"""),"#N/A") -> #N/A | L6: =IFERROR(__xludf.DUMMYFUNCTION("""COMPUTED_VALUE"""),"BB26040725") -> BB26040725 | M6: =IFERROR(__xludf.DUMMYFUNCTION("""COMPUTED_VALUE"""),"BAMBOO MG KẼM LOTUS DIỆP LỤC") -> BAMBOO MG KẼM LOTUS DIỆP LỤC | N6: =IFERROR(__xludf.DUMMYFUNCTION("""COMPUTED_VALUE"""),"13XL0017") -> 13XL0017 | O6: =IFERROR(__xludf.DUMMYFUNCTION("""COMPUTED_VALUE"""),"Phân bón vi lượng Phú Sĩ FJ-09 Kẽm Mg") -> Phân bón vi lượng Phú Sĩ FJ-09 Kẽm Mg | P6: =IFERROR(__xludf.DUMMYFUNCTION("""COMPUTED_VALUE"""),"#N/A") -> #N/A | Q6: =IFERROR(__xludf.DUMMYFUNCTION("""COMPUTED_VALUE"""),"KHÔNG KHỚP") -> KHÔNG KHỚP
A7: =IFERROR(__xludf.DUMMYFUNCTION("""COMPUTED_VALUE"""),4.0) -> 4 | B7: =IFERROR(__xludf.DUMMYFUNCTION("""COMPUTED_VALUE"""),45887.0) -> 45887 | C7: =IFERROR(__xludf.DUMMYFUNCTION("""COMPUTED_VALUE"""),1.0) -> 1 | D7: =IFERROR(__xludf.DUMMYFUNCTION("""COMPUTED_VALUE"""),"CT MỚI") -> CT MỚI | G7: =IFERROR(__xludf.DUMMYFUNCTION("""COMPUTED_VALUE"""),"HH3790") -> HH3790 | H7: =IFERROR(__xludf.DUMMYFUNCTION("""COMPUTED_VALUE"""),"CANXI BO MASTER") -> CANXI BO MASTER | I7: =IFERROR(__xludf.DUMMYFUNCTION("""COMPUTED_VALUE"""),"#N/A") -> #N/A | M7: =IFERROR(__xludf.DUMMYFUNCTION("""COMPUTED_VALUE"""),"CANXI BO MASTER") -> CANXI BO MASTER | N7: =IFERROR(__xludf.DUMMYFUNCTION("""COMPUTED_VALUE"""),"10CR0015") -> 10CR0015 | O7: =IFERROR(__xludf.DUMMYFUNCTION("""COMPUTED_VALUE"""),"Phân bón Vi lượng AGAMA-CANXI BO") -> Phân bón Vi lượng AGAMA-CANXI BO | P7: =IFERROR(__xludf.DUMMYFUNCTION("""COMPUTED_VALUE"""),"#N/A") -> #N/A | Q7: =IFERROR(__xludf.DUMMYFUNCTION("""COMPUTED_VALUE"""),"KHÔNG KHỚP") -> KHÔNG KHỚP
A8: =IFERROR(__xludf.DUMMYFUNCTION("""COMPUTED_VALUE"""),5.0) -> 5 | B8: =IFERROR(__xludf.DUMMYFUNCTION("""COMPUTED_VALUE"""),45889.0) -> 45889 | C8: =IFERROR(__xludf.DUMMYFUNCTION("""COMPUTED_VALUE"""),1.0) -> 1 | D8: =IFERROR(__xludf.DUMMYFUNCTION("""COMPUTED_VALUE"""),"CT MỚI") -> CT MỚI | G8: =IFERROR(__xludf.DUMMYFUNCTION("""COMPUTED_VALUE"""),"HH3986") -> HH3986 | H8: =IFERROR(__xludf.DUMMYFUNCTION("""COMPUTED_VALUE"""),"STOP UP IDA") -> STOP UP IDA | I8: =IFERROR(__xludf.DUMMYFUNCTION("""COMPUTED_VALUE"""),"#N/A") -> #N/A | L8: =IFERROR(__xludf.DUMMYFUNCTION("""COMPUTED_VALUE"""),"CHẶN ĐỌT DÒNG V2") -> CHẶN ĐỌT DÒNG V2 | M8: =IFERROR(__xludf.DUMMYFUNCTION("""COMPUTED_VALUE"""),"STOP UP MT STOP AGRI STOP STOP ĐỌT SIÊU CHẶN ĐỌT MASTER STOP UNI STOP ONE BAMBOO DOUBLE STOP") -> STOP UP MT STOP AGRI STOP STOP ĐỌT SIÊU CHẶN ĐỌT MASTER STOP UNI STOP ONE BAMBOO DOUBLE STOP | N8: =IFERROR(__xludf.DUMMYFUNCTION("""COMPUTED_VALUE"""),"06CD0009V1") -> 06CD0009V1 | O8: =IFERROR(__xludf.DUMMYFUNCTION("""COMPUTED_VALUE"""),"Phân bón Vi lượng Quantity New") -> Phân bón Vi lượng Quantity New | P8: =IFERROR(__xludf.DUMMYFUNCTION("""COMPUTED_VALUE"""),"#N/A") -> #N/A | Q8: =IFERROR(__xludf.DUMMYFUNCTION("""COMPUTED_VALUE"""),"KHÔNG KHỚP") -> KHÔNG KHỚP
A9: =IFERROR(__xludf.DUMMYFUNCTION("""COMPUTED_VALUE"""),6.0) -> 6 | B9: =IFERROR(__xludf.DUMMYFUNCTION("""COMPUTED_VALUE"""),"") | C9: =IFERROR(__xludf.DUMMYFUNCTION("""COMPUTED_VALUE"""),1.0) -> 1 | D9: =IFERROR(__xludf.DUMMYFUNCTION("""COMPUTED_VALUE"""),"CT MỚI") -> CT MỚI | G9: =IFERROR(__xludf.DUMMYFUNCTION("""COMPUTED_VALUE"""),"04VG0021V1-160825") -> 04VG0021V1-160825 | H9: =IFERROR(__xludf.DUMMYFUNCTION("""COMPUTED_VALUE"""),"SUPER NANO") -> SUPER NANO | I9: =IFERROR(__xludf.DUMMYFUNCTION("""COMPUTED_VALUE"""),"#N/A") -> #N/A | L9: =IFERROR(__xludf.DUMMYFUNCTION("""COMPUTED_VALUE"""),"") | M9: =IFERROR(__xludf.DUMMYFUNCTION("""COMPUTED_VALUE"""),"") | N9: =IFERROR(__xludf.DUMMYFUNCTION("""COMPUTED_VALUE"""),"04VG0021V1") -> 04VG0021V1 | O9: =IFERROR(__xludf.DUMMYFUNCTION("""COMPUTED_VALUE"""),"") | P9: =IFERROR(__xludf.DUMMYFUNCTION("""COMPUTED_VALUE"""),"#N/A") -> #N/A | Q9: =IFERROR(__xludf.DUMMYFUNCTION("""COMPUTED_VALUE"""),"KHÔNG KHỚP") -> KHÔNG KHỚP
A10: =IFERROR(__xludf.DUMMYFUNCTION("""COMPUTED_VALUE"""),7.0) -> 7 | B10: =IFERROR(__xludf.DUMMYFUNCTION("""COMPUTED_VALUE"""),45885.0) -> 45885 | C10: =IFERROR(__xludf.DUMMYFUNCTION("""COMPUTED_VALUE"""),1.0) -> 1 | D10: =IFERROR(__xludf.DUMMYFUNCTION("""COMPUTED_VALUE"""),"CT MỚI") -> CT MỚI | G10: =IFERROR(__xludf.DUMMYFUNCTION("""COMPUTED_VALUE"""),"HH3588") -> HH3588 | H10: =IFERROR(__xludf.DUMMYFUNCTION("""COMPUTED_VALUE"""),"IDA Global - I - 3888 - VG RICE 02 - 500ml - 40") -> IDA Global - I - 3888 - VG RICE 02 - 500ml - 40 | I10: =IFERROR(__xludf.DUMMYFUNCTION("""COMPUTED_VALUE"""),"#N/A") -> #N/A | L10: =IFERROR(__xludf.DUMMYFUNCTION("""COMPUTED_VALUE"""),"I02180225") -> I02180225 | M10: =IFERROR(__xludf.DUMMYFUNCTION("""COMPUTED_VALUE"""),"VG RICE 02") -> VG RICE 02 | N10: =IFERROR(__xludf.DUMMYFUNCTION("""COMPUTED_VALUE"""),"04VG0033") -> 04VG0033 | O10: =IFERROR(__xludf.DUMMYFUNCTION("""COMPUTED_VALUE"""),"Phân bón NPK-Vi lượng HC CAN") -> Phân bón NPK-Vi lượng HC CAN | P10: =IFERROR(__xludf.DUMMYFUNCTION("""COMPUTED_VALUE"""),"#N/A") -> #N/A | Q10: =IFERROR(__xludf.DUMMYFUNCTION("""COMPUTED_VALUE"""),"KHÔNG KHỚP") -> KHÔNG KHỚP
A11: =IFERROR(__xludf.DUMMYFUNCTION("""COMPUTED_VALUE"""),8.0) -> 8 | B11: =IFERROR(__xludf.DUMMYFUNCTION("""COMPUTED_VALUE"""),45885.0) -> 45885 | C11: =IFERROR(__xludf.DUMMYFUNCTION("""COMPUTED_VALUE"""),1.0) -> 1 | D11: =IFERROR(__xludf.DUMMYFUNCTION("""COMPUTED_VALUE"""),"CT MỚI") -> CT MỚI | G11: =IFERROR(__xludf.DUMMYFUNCTION("""COMPUTED_VALUE"""),"HH3860") -> HH3860 | H11: =IFERROR(__xludf.DUMMYFUNCTION("""COMPUTED_VALUE"""),"IDA Global - I - 3860 - CỨNG CÂY 304 (Nước nâu đen) - 500ml - 40") -> IDA Global - I - 3860 - CỨNG CÂY 304 (Nước nâu đen) - 500ml - 40 | I11: =IFERROR(__xludf.DUMMYFUNCTION("""COMPUTED_VALUE"""),"#N/A") -> #N/A | L11: =IFERROR(__xludf.DUMMYFUNCTION("""COMPUTED_VALUE"""),"L01261124") -> L01261124 | M11: =IFERROR(__xludf.DUMMYFUNCTION("""COMPUTED_VALUE"""),"CỨNG CÂY 304") -> CỨNG CÂY 304 | N11: =IFERROR(__xludf.DUMMYFUNCTION("""COMPUTED_VALUE"""),"02CC0002V1") -> 02CC0002V1 | O11: =IFERROR(__xludf.DUMMYFUNCTION("""COMPUTED_VALUE"""),"Phân bón Hữu cơ SH Agro Organic Fertilizer 20") -> Phân bón Hữu cơ SH Agro Organic Fertilizer 20 | P11: =IFERROR(__xludf.DUMMYFUNCTION("""COMPUTED_VALUE"""),"#N/A") -> #N/A | Q11: =IFERROR(__xludf.DUMMYFUNCTION("""COMPUTED_VALUE"""),"KHÔNG KHỚP") -> KHÔNG KHỚP
A12: =IFERROR(__xludf.DUMMYFUNCTION("""COMPUTED_VALUE"""),9.0) -> 9 | B12: =IFERROR(__xludf.DUMMYFUNCTION("""COMPUTED_VALUE"""),45889.0) -> 45889 | C12: =IFERROR(__xludf.DUMMYFUNCTION("""COMPUTED_VALUE"""),1.0) -> 1 | D12: =IFERROR(__xludf.DUMMYFUNCTION("""COMPUTED_VALUE"""),"CT MỚI") -> CT MỚI | G12: =IFERROR(__xludf.DUMMYFUNCTION("""COMPUTED_VALUE"""),"HH3971") -> HH3971 | H12: =IFERROR(__xludf.DUMMYFUNCTION("""COMPUTED_VALUE"""),"GC - IV - 3971 - Cty Thành Công Agri - MASTER STOP (nước nâu đen V2) - 1L - 20") -> GC - IV - 3971 - Cty Thành Công Agri - MASTER STOP (nước nâu đen V2) - 1L - 20 | I12: =IFERROR(__xludf.DUMMYFUNCTION("""COMPUTED_VALUE"""),"#N/A") -> #N/A | L12: =IFERROR(__xludf.DUMMYFUNCTION("""COMPUTED_VALUE"""),"CHẶN ĐỌT DÒNG V2") -> CHẶN ĐỌT DÒNG V2 | M12: =IFERROR(__xludf.DUMMYFUNCTION("""COMPUTED_VALUE"""),"STOP UP MT STOP AGRI STOP STOP ĐỌT SIÊU CHẶN ĐỌT MASTER STOP UNI STOP ONE BAMBOO DOUBLE STOP") -> STOP UP MT STOP AGRI STOP STOP ĐỌT SIÊU CHẶN ĐỌT MASTER STOP UNI STOP ONE BAMBOO DOUBLE STOP | N12: =IFERROR(__xludf.DUMMYFUNCTION("""COMPUTED_VALUE"""),"06CD0009V1") -> 06CD0009V1 | O12: =IFERROR(__xludf.DUMMYFUNCTION("""COMPUTED_VALUE"""),"Phân bón Vi lượng Quantity New") -> Phân bón Vi lượng Quantity New | P12: =IFERROR(__xludf.DUMMYFUNCTION("""COMPUTED_VALUE"""),"#N/A") -> #N/A | Q12: =IFERROR(__xludf.DUMMYFUNCTION("""COMPUTED_VALUE"""),"KHÔNG KHỚP") -> KHÔNG KHỚP
A13: =IFERROR(__xludf.DUMMYFUNCTION("""COMPUTED_VALUE"""),10.0) -> 10 | B13: =IFERROR(__xludf.DUMMYFUNCTION("""COMPUTED_VALUE"""),45889.0) -> 45889 | C13: =IFERROR(__xludf.DUMMYFUNCTION("""COMPUTED_VALUE"""),1.0) -> 1 | D13: =IFERROR(__xludf.DUMMYFUNCTION("""COMPUTED_VALUE"""),"CT MỚI") -> CT MỚI | G13: =IFERROR(__xludf.DUMMYFUNCTION("""COMPUTED_VALUE"""),"HH3845") -> HH3845 | H13: =IFERROR(__xludf.DUMMYFUNCTION("""COMPUTED_VALUE"""),"BAMBOO - VI - 3845 - BAMBOO DOUBLE STOP (nước nâu đen) - 1L - 20") -> BAMBOO - VI - 3845 - BAMBOO DOUBLE STOP (nước nâu đen) - 1L - 20 | I13: =IFERROR(__xludf.DUMMYFUNCTION("""COMPUTED_VALUE"""),"#N/A") -> #N/A | L13: =IFERROR(__xludf.DUMMYFUNCTION("""COMPUTED_VALUE"""),"CHẶN ĐỌT DÒNG V2") -> CHẶN ĐỌT DÒNG V2 | M13: =IFERROR(__xludf.DUMMYFUNCTION("""COMPUTED_VALUE"""),"STOP UP MT STOP AGRI STOP STOP ĐỌT SIÊU CHẶN ĐỌT MASTER STOP UNI STOP ONE BAMBOO DOUBLE STOP") -> STOP UP MT STOP AGRI STOP STOP ĐỌT SIÊU CHẶN ĐỌT MASTER STOP UNI STOP ONE BAMBOO DOUBLE STOP | N13: =IFERROR(__xludf.DUMMYFUNCTION("""COMPUTED_VALUE"""),"06CD0009V1") -> 06CD0009V1 | O13: =IFERROR(__xludf.DUMMYFUNCTION("""COMPUTED_VALUE"""),"Phân bón Vi lượng Quantity New") -> Phân bón Vi lượng Quantity New | P13: =IFERROR(__xludf.DUMMYFUNCTION("""COMPUTED_VALUE"""),"#N/A") -> #N/A | Q13: =IFERROR(__xludf.DUMMYFUNCTION("""COMPUTED_VALUE"""),"KHÔNG KHỚP") -> KHÔNG KHỚP
A14: =IFERROR(__xludf.DUMMYFUNCTION("""COMPUTED_VALUE"""),11.0) -> 11 | B14: =IFERROR(__xludf.DUMMYFUNCTION("""COMPUTED_VALUE"""),45889.0) -> 45889 | C14: =IFERROR(__xludf.DUMMYFUNCTION("""COMPUTED_VALUE"""),1.0) -> 1 | D14: =IFERROR(__xludf.DUMMYFUNCTION("""COMPUTED_VALUE"""),"CT MỚI") -> CT MỚI | G14: =IFERROR(__xludf.DUMMYFUNCTION("""COMPUTED_VALUE"""),"HH3991") -> HH3991 | H14: =IFERROR(__xludf.DUMMYFUNCTION("""COMPUTED_VALUE"""),"GC - IV - 3991 - Cty Thành Công Agri - MASTER STOP (nước nâu đen V2) - 1L - 20") -> GC - IV - 3991 - Cty Thành Công Agri - MASTER STOP (nước nâu đen V2) - 1L - 20 | I14: =IFERROR(__xludf.DUMMYFUNCTION("""COMPUTED_VALUE"""),"#N/A") -> #N/A | L14: =IFERROR(__xludf.DUMMYFUNCTION("""COMPUTED_VALUE"""),"CHẶN ĐỌT DÒNG V2") -> CHẶN ĐỌT DÒNG V2 | M14: =IFERROR(__xludf.DUMMYFUNCTION("""COMPUTED_VALUE"""),"STOP UP MT STOP AGRI STOP STOP ĐỌT SIÊU CHẶN ĐỌT MASTER STOP UNI STOP ONE BAMBOO DOUBLE STOP") -> STOP UP MT STOP AGRI STOP STOP ĐỌT SIÊU CHẶN ĐỌT MASTER STOP UNI STOP ONE BAMBOO DOUBLE STOP | N14: =IFERROR(__xludf.DUMMYFUNCTION("""COMPUTED_VALUE"""),"06CD0009V1") -> 06CD0009V1 | O14: =IFERROR(__xludf.DUMMYFUNCTION("""COMPUTED_VALUE"""),"Phân bón Vi lượng Quantity New") -> Phân bón Vi lượng Quantity New | P14: =IFERROR(__xludf.DUMMYFUNCTION("""COMPUTED_VALUE"""),"#N/A") -> #N/A | Q14: =IFERROR(__xludf.DUMMYFUNCTION("""COMPUTED_VALUE"""),"KHÔNG KHỚP") -> KHÔNG KHỚP
A15: =IFERROR(__xludf.DUMMYFUNCTION("""COMPUTED_VALUE"""),12.0) -> 12 | B15: =IFERROR(__xludf.DUMMYFUNCTION("""COMPUTED_VALUE"""),45889.0) -> 45889 | C15: =IFERROR(__xludf.DUMMYFUNCTION("""COMPUTED_VALUE"""),1.0) -> 1 | D15: =IFERROR(__xludf.DUMMYFUNCTION("""COMPUTED_VALUE"""),"CT MỚI") -> CT MỚI | G15: =IFERROR(__xludf.DUMMYFUNCTION("""COMPUTED_VALUE"""),"HH3996") -> HH3996 | H15: =IFERROR(__xludf.DUMMYFUNCTION("""COMPUTED_VALUE"""),"GC - IV - 3996 - CTY DONA VINA - UNI-STOP ONE (Nước nâu đen) - 1L - 20") -> GC - IV - 3996 - CTY DONA VINA - UNI-STOP ONE (Nước nâu đen) - 1L - 20 | I15: =IFERROR(__xludf.DUMMYFUNCTION("""COMPUTED_VALUE"""),"#N/A") -> #N/A | L15: =IFERROR(__xludf.DUMMYFUNCTION("""COMPUTED_VALUE"""),"CHẶN ĐỌT DÒNG V2") -> CHẶN ĐỌT DÒNG V2 | M15: =IFERROR(__xludf.DUMMYFUNCTION("""COMPUTED_VALUE"""),"STOP UP MT STOP AGRI STOP STOP ĐỌT SIÊU CHẶN ĐỌT MASTER STOP UNI STOP ONE BAMBOO DOUBLE STOP") -> STOP UP MT STOP AGRI STOP STOP ĐỌT SIÊU CHẶN ĐỌT MASTER STOP UNI STOP ONE BAMBOO DOUBLE STOP | N15: =IFERROR(__xludf.DUMMYFUNCTION("""COMPUTED_VALUE"""),"06CD0009V1") -> 06CD0009V1 | O15: =IFERROR(__xludf.DUMMYFUNCTION("""COMPUTED_VALUE"""),"Phân bón Vi lượng Quantity New") -> Phân bón Vi lượng Quantity New | P15: =IFERROR(__xludf.DUMMYFUNCTION("""COMPUTED_VALUE"""),"#N/A") -> #N/A | Q15: =IFERROR(__xludf.DUMMYFUNCTION("""COMPUTED_VALUE"""),"KHÔNG KHỚP") -> KHÔNG KHỚP
A16: =IFERROR(__xludf.DUMMYFUNCTION("""COMPUTED_VALUE"""),13.0) -> 13 | B16: =IFERROR(__xludf.DUMMYFUNCTION("""COMPUTED_VALUE"""),45890.0) -> 45890 | C16: =IFERROR(__xludf.DUMMYFUNCTION("""COMPUTED_VALUE"""),1.0) -> 1 | D16: =IFERROR(__xludf.DUMMYFUNCTION("""COMPUTED_VALUE"""),"CT MỚI") -> CT MỚI | G16: =IFERROR(__xludf.DUMMYFUNCTION("""COMPUTED_VALUE"""),"HH4011") -> HH4011 | H16: =IFERROR(__xludf.DUMMYFUNCTION("""COMPUTED_VALUE"""),"10th Kodo Stop") -> 10th Kodo Stop | I16: =IFERROR(__xludf.DUMMYFUNCTION("""COMPUTED_VALUE"""),"#N/A") -> #N/A | L16: =IFERROR(__xludf.DUMMYFUNCTION("""COMPUTED_VALUE"""),"CHẶN ĐỌT DÒNG V1") -> CHẶN ĐỌT DÒNG V1 | M16: =IFERROR(__xludf.DUMMYFUNCTION("""COMPUTED_VALUE"""),"KODO STOP") -> KODO STOP | N16: =IFERROR(__xludf.DUMMYFUNCTION("""COMPUTED_VALUE"""),"06CD0006") -> 06CD0006 | O16: =IFERROR(__xludf.DUMMYFUNCTION("""COMPUTED_VALUE"""),"Phân bón Vi lượng Quantity New") -> Phân bón Vi lượng Quantity New | P16: =IFERROR(__xludf.DUMMYFUNCTION("""COMPUTED_VALUE"""),"#N/A") -> #N/A | Q16: =IFERROR(__xludf.DUMMYFUNCTION("""COMPUTED_VALUE"""),"KHÔNG KHỚP") -> KHÔNG KHỚP
A17: =IFERROR(__xludf.DUMMYFUNCTION("""COMPUTED_VALUE"""),14.0) -> 14 | B17: =IFERROR(__xludf.DUMMYFUNCTION("""COMPUTED_VALUE"""),45887.0) -> 45887 | C17: =IFERROR(__xludf.DUMMYFUNCTION("""COMPUTED_VALUE"""),1.0) -> 1 | D17: =IFERROR(__xludf.DUMMYFUNCTION("""COMPUTED_VALUE"""),"CT MỚI") -> CT MỚI | G17: =IFERROR(__xludf.DUMMYFUNCTION("""COMPUTED_VALUE"""),"HH3975") -> HH3975 | H17: =IFERROR(__xludf.DUMMYFUNCTION("""COMPUTED_VALUE"""),"15th Chuyên gia to trái") -> 15th Chuyên gia to trái | I17: =IFERROR(__xludf.DUMMYFUNCTION("""COMPUTED_VALUE"""),"#N/A") -> #N/A | L17: =IFERROR(__xludf.DUMMYFUNCTION("""COMPUTED_VALUE"""),"A09070825") -> A09070825 | M17: =IFERROR(__xludf.DUMMYFUNCTION("""COMPUTED_VALUE"""),"TO TRÁI") -> TO TRÁI | N17: =IFERROR(__xludf.DUMMYFUNCTION("""COMPUTED_VALUE"""),"11TT0017") -> 11TT0017 | O17: =IFERROR(__xludf.DUMMYFUNCTION("""COMPUTED_VALUE"""),"Phân bón Vi lượng Quantity New") -> Phân bón Vi lượng Quantity New | P17: =IFERROR(__xludf.DUMMYFUNCTION("""COMPUTED_VALUE"""),"#N/A") -> #N/A | Q17: =IFERROR(__xludf.DUMMYFUNCTION("""COMPUTED_VALUE"""),"KHÔNG KHỚP") -> KHÔNG KHỚP
A18: =IFERROR(__xludf.DUMMYFUNCTION("""COMPUTED_VALUE"""),15.0) -> 15 | B18: =IFERROR(__xludf.DUMMYFUNCTION("""COMPUTED_VALUE"""),45888.0) -> 45888 | C18: =IFERROR(__xludf.DUMMYFUNCTION("""COMPUTED_VALUE"""),1.0) -> 1 | D18: =IFERROR(__xludf.DUMMYFUNCTION("""COMPUTED_VALUE"""),"CT MỚI") -> CT MỚI | G18: =IFERROR(__xludf.DUMMYFUNCTION("""COMPUTED_VALUE"""),"NA0012V2") -> NA0012V2 | H18: =IFERROR(__xludf.DUMMYFUNCTION("""COMPUTED_VALUE"""),"Phụ gia NA0012V2") -> Phụ gia NA0012V2 | I18: =IFERROR(__xludf.DUMMYFUNCTION("""COMPUTED_VALUE"""),"#N/A") -> #N/A | M18: =IFERROR(__xludf.DUMMYFUNCTION("""COMPUTED_VALUE"""),"PHỤ GIA NA0012V2") -> PHỤ GIA NA0012V2 | N18: =IFERROR(__xludf.DUMMYFUNCTION("""COMPUTED_VALUE"""),"NA0012V2") -> NA0012V2 | P18: =IFERROR(__xludf.DUMMYFUNCTION("""COMPUTED_VALUE"""),"#N/A") -> #N/A | Q18: =IFERROR(__xludf.DUMMYFUNCTION("""COMPUTED_VALUE"""),"KHÔNG KHỚP") -> KHÔNG KHỚP
A19: =IFERROR(__xludf.DUMMYFUNCTION("""COMPUTED_VALUE"""),16.0) -> 16 | B19: =IFERROR(__xludf.DUMMYFUNCTION("""COMPUTED_VALUE"""),45888.0) -> 45888 | C19: =IFERROR(__xludf.DUMMYFUNCTION("""COMPUTED_VALUE"""),1.0) -> 1 | D19: =IFERROR(__xludf.DUMMYFUNCTION("""COMPUTED_VALUE"""),"CT MỚI") -> CT MỚI | G19: =IFERROR(__xludf.DUMMYFUNCTION("""COMPUTED_VALUE"""),"HH3925") -> HH3925 | H19: =IFERROR(__xludf.DUMMYFUNCTION("""COMPUTED_VALUE"""),"GC - IV - 3925 - Cty Newtex - ĐÒNG TO BÔNG KẸO T7 (Dạng SC màu vàng nhạt) - 500ml - 40") -> GC - IV - 3925 - Cty Newtex - ĐÒNG TO BÔNG KẸO T7 (Dạng SC màu vàng nhạt) - 500ml - 40 | I19: =IFERROR(__xludf.DUMMYFUNCTION("""COMPUTED_VALUE"""),"#N/A") -> #N/A | L19: =IFERROR(__xludf.DUMMYFUNCTION("""COMPUTED_VALUE"""),"A03260525") -> A03260525 | M19: =IFERROR(__xludf.DUMMYFUNCTION("""COMPUTED_VALUE"""),"TO ĐỒNG") -> TO ĐỒNG | N19: =IFERROR(__xludf.DUMMYFUNCTION("""COMPUTED_VALUE"""),"03DD0017") -> 03DD0017 | O19: =IFERROR(__xludf.DUMMYFUNCTION("""COMPUTED_VALUE"""),"Phân bón lá NPK-Vi lượng GNC 19") -> Phân bón lá NPK-Vi lượng GNC 19 | P19: =IFERROR(__xludf.DUMMYFUNCTION("""COMPUTED_VALUE"""),"#N/A") -> #N/A | Q19: =IFERROR(__xludf.DUMMYFUNCTION("""COMPUTED_VALUE"""),"KHÔNG KHỚP") -> KHÔNG KHỚP
A20: =IFERROR(__xludf.DUMMYFUNCTION("""COMPUTED_VALUE"""),17.0) -> 17 | B20: =IFERROR(__xludf.DUMMYFUNCTION("""COMPUTED_VALUE"""),45887.0) -> 45887 | C20: =IFERROR(__xludf.DUMMYFUNCTION("""COMPUTED_VALUE"""),1.0) -> 1 | D20: =IFERROR(__xludf.DUMMYFUNCTION("""COMPUTED_VALUE"""),"CT MỚI") -> CT MỚI | G20: =IFERROR(__xludf.DUMMYFUNCTION("""COMPUTED_VALUE"""),"HH3905") -> HH3905 | H20: =IFERROR(__xludf.DUMMYFUNCTION("""COMPUTED_VALUE"""),"IDA Global - I - 3905 - WINNER X2 (Nước đỏ cam) - 500ml - 40") -> IDA Global - I - 3905 - WINNER X2 (Nước đỏ cam) - 500ml - 40 | I20: =IFERROR(__xludf.DUMMYFUNCTION("""COMPUTED_VALUE"""),"#N/A") -> #N/A | M20: =IFERROR(__xludf.DUMMYFUNCTION("""COMPUTED_VALUE"""),"WINNER X2") -> WINNER X2 | N20: =IFERROR(__xludf.DUMMYFUNCTION("""COMPUTED_VALUE"""),"04VG0015") -> 04VG0015 | O20: =IFERROR(__xludf.DUMMYFUNCTION("""COMPUTED_VALUE"""),"Phân bón NPK-Vi lượng MASSIVE-BLUE") -> Phân bón NPK-Vi lượng MASSIVE-BLUE | P20: =IFERROR(__xludf.DUMMYFUNCTION("""COMPUTED_VALUE"""),"#N/A") -> #N/A | Q20: =IFERROR(__xludf.DUMMYFUNCTION("""COMPUTED_VALUE"""),"KHÔNG KHỚP") -> KHÔNG KHỚP
A21: =IFERROR(__xludf.DUMMYFUNCTION("""COMPUTED_VALUE"""),18.0) -> 18 | B21: =IFERROR(__xludf.DUMMYFUNCTION("""COMPUTED_VALUE"""),45892.0) -> 45892 | C21: =IFERROR(__xludf.DUMMYFUNCTION("""COMPUTED_VALUE"""),1.0) -> 1 | D21: =IFERROR(__xludf.DUMMYFUNCTION("""COMPUTED_VALUE"""),"CT MỚI") -> CT MỚI | G21: =IFERROR(__xludf.DUMMYFUNCTION("""COMPUTED_VALUE"""),"HH4012") -> HH4012 | H21: =IFERROR(__xludf.DUMMYFUNCTION("""COMPUTED_VALUE"""),"GC - V - 4012 - N2SBIO - N2 PHYTO PLUS (Nước nâu đen) - 500ml - 40") -> GC - V - 4012 - N2SBIO - N2 PHYTO PLUS (Nước nâu đen) - 500ml - 40 | I21: =IFERROR(__xludf.DUMMYFUNCTION("""COMPUTED_VALUE"""),"#N/A") -> #N/A | L21: =IFERROR(__xludf.DUMMYFUNCTION("""COMPUTED_VALUE"""),"N05181224 X06121224") -> N05181224 X06121224 | M21: =IFERROR(__xludf.DUMMYFUNCTION("""COMPUTED_VALUE"""),"N2 PHYTO PLUS DR.AB MAGSI") -> N2 PHYTO PLUS DR.AB MAGSI | N21: =IFERROR(__xludf.DUMMYFUNCTION("""COMPUTED_VALUE"""),"02CC0009V1") -> 02CC0009V1 | O21: =IFERROR(__xludf.DUMMYFUNCTION("""COMPUTED_VALUE"""),"Phân bón Hữu cơ SH Agro Organic Fertilizer 20") -> Phân bón Hữu cơ SH Agro Organic Fertilizer 20 | P21: =IFERROR(__xludf.DUMMYFUNCTION("""COMPUTED_VALUE"""),"#N/A") -> #N/A | Q21: =IFERROR(__xludf.DUMMYFUNCTION("""COMPUTED_VALUE"""),"KHÔNG KHỚP") -> KHÔNG KHỚP
A22: =IFERROR(__xludf.DUMMYFUNCTION("""COMPUTED_VALUE"""),19.0) -> 19 | B22: =IFERROR(__xludf.DUMMYFUNCTION("""COMPUTED_VALUE"""),45891.0) -> 45891 | C22: =IFERROR(__xludf.DUMMYFUNCTION("""COMPUTED_VALUE"""),1.0) -> 1 | D22: =IFERROR(__xludf.DUMMYFUNCTION("""COMPUTED_VALUE"""),"CT MỚI") -> CT MỚI | G22: =IFERROR(__xludf.DUMMYFUNCTION("""COMPUTED_VALUE"""),"NA0012V1") -> NA0012V1 | H22: =IFERROR(__xludf.DUMMYFUNCTION("""COMPUTED_VALUE"""),"PHỤ GIA NA0012V1") -> PHỤ GIA NA0012V1 | I22: =IFERROR(__xludf.DUMMYFUNCTION("""COMPUTED_VALUE"""),"#N/A") -> #N/A | M22: =IFERROR(__xludf.DUMMYFUNCTION("""COMPUTED_VALUE"""),"PHỤ GIA NA0012V1") -> PHỤ GIA NA0012V1 | N22: =IFERROR(__xludf.DUMMYFUNCTION("""COMPUTED_VALUE"""),"NA0012V1") -> NA0012V1 | P22: =IFERROR(__xludf.DUMMYFUNCTION("""COMPUTED_VALUE"""),"#N/A") -> #N/A | Q22: =IFERROR(__xludf.DUMMYFUNCTION("""COMPUTED_VALUE"""),"KHÔNG KHỚP") -> KHÔNG KHỚP
A23: =IFERROR(__xludf.DUMMYFUNCTION("""COMPUTED_VALUE"""),20.0) -> 20 | B23: =IFERROR(__xludf.DUMMYFUNCTION("""COMPUTED_VALUE"""),45892.0) -> 45892 | C23: =IFERROR(__xludf.DUMMYFUNCTION("""COMPUTED_VALUE"""),1.0) -> 1 | D23: =IFERROR(__xludf.DUMMYFUNCTION("""COMPUTED_VALUE"""),"CT MỚI") -> CT MỚI | G23: =IFERROR(__xludf.DUMMYFUNCTION("""COMPUTED_VALUE"""),"HH3850") -> HH3850 | H23: =IFERROR(__xludf.DUMMYFUNCTION("""COMPUTED_VALUE"""),"GC - IV - 3850 - NHP GROUP - ULTRA KEO GROW (Nước nâu đen) - 200ml - 40") -> GC - IV - 3850 - NHP GROUP - ULTRA KEO GROW (Nước nâu đen) - 200ml - 40 | I23: =IFERROR(__xludf.DUMMYFUNCTION("""COMPUTED_VALUE"""),"#N/A") -> #N/A | L23: =IFERROR(__xludf.DUMMYFUNCTION("""COMPUTED_VALUE"""),"A04071024") -> A04071024 | M23: =IFERROR(__xludf.DUMMYFUNCTION("""COMPUTED_VALUE"""),"ULTRA KEO GROW") -> ULTRA KEO GROW | N23: =IFERROR(__xludf.DUMMYFUNCTION("""COMPUTED_VALUE"""),"01RR0037V1") -> 01RR0037V1 | O23: =IFERROR(__xludf.DUMMYFUNCTION("""COMPUTED_VALUE"""),"Phân bón Hữu cơ SH Agro Organic Fertilizer 20") -> Phân bón Hữu cơ SH Agro Organic Fertilizer 20 | P23: =IFERROR(__xludf.DUMMYFUNCTION("""COMPUTED_VALUE"""),"#N/A") -> #N/A | Q23: =IFERROR(__xludf.DUMMYFUNCTION("""COMPUTED_VALUE"""),"KHÔNG KHỚP") -> KHÔNG KHỚP
A24: =IFERROR(__xludf.DUMMYFUNCTION("""COMPUTED_VALUE"""),21.0) -> 21 | B24: =IFERROR(__xludf.DUMMYFUNCTION("""COMPUTED_VALUE"""),45890.0) -> 45890 | C24: =IFERROR(__xludf.DUMMYFUNCTION("""COMPUTED_VALUE"""),1.0) -> 1 | D24: =IFERROR(__xludf.DUMMYFUNCTION("""COMPUTED_VALUE"""),"CT MỚI") -> CT MỚI | G24: =IFERROR(__xludf.DUMMYFUNCTION("""COMPUTED_VALUE"""),"HH3968") -> HH3968 | H24: =IFERROR(__xludf.DUMMYFUNCTION("""COMPUTED_VALUE"""),"BAMBOO - VI - 3968 - BAMBOO 777 TE (chưa xác định) - 1L - 20") -> BAMBOO - VI - 3968 - BAMBOO 777 TE (chưa xác định) - 1L - 20 | I24: =IFERROR(__xludf.DUMMYFUNCTION("""COMPUTED_VALUE"""),"#N/A") -> #N/A | L24: =IFERROR(__xludf.DUMMYFUNCTION("""COMPUTED_VALUE"""),"BB25040725") -> BB25040725 | M24: =IFERROR(__xludf.DUMMYFUNCTION("""COMPUTED_VALUE"""),"BAMBOO 777 TE") -> BAMBOO 777 TE | N24: =IFERROR(__xludf.DUMMYFUNCTION("""COMPUTED_VALUE"""),"03DD0015") -> 03DD0015 | O24: =IFERROR(__xludf.DUMMYFUNCTION("""COMPUTED_VALUE"""),"Phân bón lá NPK-Vi lượng GNC 19") -> Phân bón lá NPK-Vi lượng GNC 19 | P24: =IFERROR(__xludf.DUMMYFUNCTION("""COMPUTED_VALUE"""),"#N/A") -> #N/A | Q24: =IFERROR(__xludf.DUMMYFUNCTION("""COMPUTED_VALUE"""),"KHÔNG KHỚP") -> KHÔNG KHỚP
A25: =IFERROR(__xludf.DUMMYFUNCTION("""COMPUTED_VALUE"""),22.0) -> 22 | B25: =IFERROR(__xludf.DUMMYFUNCTION("""COMPUTED_VALUE"""),45890.0) -> 45890 | C25: =IFERROR(__xludf.DUMMYFUNCTION("""COMPUTED_VALUE"""),1.0) -> 1 | D25: =IFERROR(__xludf.DUMMYFUNCTION("""COMPUTED_VALUE"""),"CT MỚI") -> CT MỚI | G25: =IFERROR(__xludf.DUMMYFUNCTION("""COMPUTED_VALUE"""),"HH3966") -> HH3966 | H25: =IFERROR(__xludf.DUMMYFUNCTION("""COMPUTED_VALUE"""),"BAMBOO - VI - 3966 - BAMBOO 5.10.8 TE (chưa xác định) - 500ml - 40") -> BAMBOO - VI - 3966 - BAMBOO 5.10.8 TE (chưa xác định) - 500ml - 40 | I25: =IFERROR(__xludf.DUMMYFUNCTION("""COMPUTED_VALUE"""),"#N/A") -> #N/A | L25: =IFERROR(__xludf.DUMMYFUNCTION("""COMPUTED_VALUE"""),"BB27040725") -> BB27040725 | M25: =IFERROR(__xludf.DUMMYFUNCTION("""COMPUTED_VALUE"""),"BAMBOO 5.10.8 TE") -> BAMBOO 5.10.8 TE | N25: =IFERROR(__xludf.DUMMYFUNCTION("""COMPUTED_VALUE"""),"03DD0016") -> 03DD0016 | O25: =IFERROR(__xludf.DUMMYFUNCTION("""COMPUTED_VALUE"""),"Phân bón hỗn hợp NPK GBUMPER 02") -> Phân bón hỗn hợp NPK GBUMPER 02 | P25: =IFERROR(__xludf.DUMMYFUNCTION("""COMPUTED_VALUE"""),"#N/A") -> #N/A | Q25: =IFERROR(__xludf.DUMMYFUNCTION("""COMPUTED_VALUE"""),"KHÔNG KHỚP") -> KHÔNG KHỚP
A26: =IFERROR(__xludf.DUMMYFUNCTION("""COMPUTED_VALUE"""),23.0) -> 23 | B26: =IFERROR(__xludf.DUMMYFUNCTION("""COMPUTED_VALUE"""),45890.0) -> 45890 | C26: =IFERROR(__xludf.DUMMYFUNCTION("""COMPUTED_VALUE"""),1.0) -> 1 | D26: =IFERROR(__xludf.DUMMYFUNCTION("""COMPUTED_VALUE"""),"CT MỚI") -> CT MỚI | G26: =IFERROR(__xludf.DUMMYFUNCTION("""COMPUTED_VALUE"""),"HH4017") -> HH4017 | H26: =IFERROR(__xludf.DUMMYFUNCTION("""COMPUTED_VALUE"""),"GC - II - 4017 - LOT AGC - Nguyễn Văn Hiệp - DR.H2 (Nước nâu đen) - 1L - 20") -> GC - II - 4017 - LOT AGC - Nguyễn Văn Hiệp - DR.H2 (Nước nâu đen) - 1L - 20 | I26: =IFERROR(__xludf.DUMMYFUNCTION("""COMPUTED_VALUE"""),"#N/A") -> #N/A | L26: =IFERROR(__xludf.DUMMYFUNCTION("""COMPUTED_VALUE"""),"CHẶN ĐỌT DÒNG V1") -> CHẶN ĐỌT DÒNG V1 | M26: =IFERROR(__xludf.DUMMYFUNCTION("""COMPUTED_VALUE"""),"KODO STOP") -> KODO STOP | N26: =IFERROR(__xludf.DUMMYFUNCTION("""COMPUTED_VALUE"""),"06CD0006") -> 06CD0006 | O26: =IFERROR(__xludf.DUMMYFUNCTION("""COMPUTED_VALUE"""),"Phân bón Vi lượng Quantity New") -> Phân bón Vi lượng Quantity New | P26: =IFERROR(__xludf.DUMMYFUNCTION("""COMPUTED_VALUE"""),"#N/A") -> #N/A | Q26: =IFERROR(__xludf.DUMMYFUNCTION("""COMPUTED_VALUE"""),"KHÔNG KHỚP") -> KHÔNG KHỚP
A27: =IFERROR(__xludf.DUMMYFUNCTION("""COMPUTED_VALUE"""),24.0) -> 24 | B27: =IFERROR(__xludf.DUMMYFUNCTION("""COMPUTED_VALUE"""),45892.0) -> 45892 | C27: =IFERROR(__xludf.DUMMYFUNCTION("""COMPUTED_VALUE"""),1.0) -> 1 | D27: =IFERROR(__xludf.DUMMYFUNCTION("""COMPUTED_VALUE"""),"CT MỚI") -> CT MỚI | G27: =IFERROR(__xludf.DUMMYFUNCTION("""COMPUTED_VALUE"""),"HH3877") -> HH3877 | H27: =IFERROR(__xludf.DUMMYFUNCTION("""COMPUTED_VALUE"""),"GC - II - 3877 - GC.NANOFISH - STOP 25 (nước nâu đen) - 1L - 20") -> GC - II - 3877 - GC.NANOFISH - STOP 25 (nước nâu đen) - 1L - 20 | I27: =IFERROR(__xludf.DUMMYFUNCTION("""COMPUTED_VALUE"""),"#N/A") -> #N/A | L27: =IFERROR(__xludf.DUMMYFUNCTION("""COMPUTED_VALUE"""),"CHẶN ĐỌT DÒNG V3") -> CHẶN ĐỌT DÒNG V3 | M27: =IFERROR(__xludf.DUMMYFUNCTION("""COMPUTED_VALUE"""),"KODO STOP SIÊU CHẶN ĐỌT STOP 25 UNI STOP UNI STOP 25") -> KODO STOP SIÊU CHẶN ĐỌT STOP 25 UNI STOP UNI STOP 25 | N27: =IFERROR(__xludf.DUMMYFUNCTION("""COMPUTED_VALUE"""),"06CD0007") -> 06CD0007 | O27: =IFERROR(__xludf.DUMMYFUNCTION("""COMPUTED_VALUE"""),"Phân bón Vi lượng Quantity New") -> Phân bón Vi lượng Quantity New | P27: =IFERROR(__xludf.DUMMYFUNCTION("""COMPUTED_VALUE"""),"#N/A") -> #N/A | Q27: =IFERROR(__xludf.DUMMYFUNCTION("""COMPUTED_VALUE"""),"KHÔNG KHỚP") -> KHÔNG KHỚP
A28: =IFERROR(__xludf.DUMMYFUNCTION("""COMPUTED_VALUE"""),25.0) -> 25 | B28: =IFERROR(__xludf.DUMMYFUNCTION("""COMPUTED_VALUE"""),45892.0) -> 45892 | C28: =IFERROR(__xludf.DUMMYFUNCTION("""COMPUTED_VALUE"""),1.0) -> 1 | D28: =IFERROR(__xludf.DUMMYFUNCTION("""COMPUTED_VALUE"""),"CT MỚI") -> CT MỚI | G28: =IFERROR(__xludf.DUMMYFUNCTION("""COMPUTED_VALUE"""),"HH2641") -> HH2641 | H28: =IFERROR(__xludf.DUMMYFUNCTION("""COMPUTED_VALUE"""),"GC - IV - 2641 - GNH - SIÊU TẠO NỤ (Nước nâu đen) - 500ml - 40") -> GC - IV - 2641 - GNH - SIÊU TẠO NỤ (Nước nâu đen) - 500ml - 40 | I28: =IFERROR(__xludf.DUMMYFUNCTION("""COMPUTED_VALUE"""),"#N/A") -> #N/A | L28: =IFERROR(__xludf.DUMMYFUNCTION("""COMPUTED_VALUE"""),"A05120724") -> A05120724 | M28: =IFERROR(__xludf.DUMMYFUNCTION("""COMPUTED_VALUE"""),"SIÊU TẠO NỤ") -> SIÊU TẠO NỤ | N28: =IFERROR(__xludf.DUMMYFUNCTION("""COMPUTED_VALUE"""),"08TM0015") -> 08TM0015 | O28: =IFERROR(__xludf.DUMMYFUNCTION("""COMPUTED_VALUE"""),"Phân bón Vi lượng AGAMA-SUPPORT") -> Phân bón Vi lượng AGAMA-SUPPORT | P28: =IFERROR(__xludf.DUMMYFUNCTION("""COMPUTED_VALUE"""),"#N/A") -> #N/A | Q28: =IFERROR(__xludf.DUMMYFUNCTION("""COMPUTED_VALUE"""),"KHÔNG KHỚP") -> KHÔNG KHỚP
A29: =IFERROR(__xludf.DUMMYFUNCTION("""COMPUTED_VALUE"""),26.0) -> 26 | B29: =IFERROR(__xludf.DUMMYFUNCTION("""COMPUTED_VALUE"""),45892.0) -> 45892 | C29: =IFERROR(__xludf.DUMMYFUNCTION("""COMPUTED_VALUE"""),1.0) -> 1 | D29: =IFERROR(__xludf.DUMMYFUNCTION("""COMPUTED_VALUE"""),"CT MỚI") -> CT MỚI | G29: =IFERROR(__xludf.DUMMYFUNCTION("""COMPUTED_VALUE"""),"HH2748") -> HH2748 | H29: =IFERROR(__xludf.DUMMYFUNCTION("""COMPUTED_VALUE"""),"GC - II - 2748 - CSSX An Khang (A.Dinh) - TAK20 (Bột màu trắng) - 1kg - 20") -> GC - II - 2748 - CSSX An Khang (A.Dinh) - TAK20 (Bột màu trắng) - 1kg - 20 | I29: =IFERROR(__xludf.DUMMYFUNCTION("""COMPUTED_VALUE"""),"#N/A") -> #N/A | L29: =IFERROR(__xludf.DUMMYFUNCTION("""COMPUTED_VALUE"""),"A05200824") -> A05200824 | M29: =IFERROR(__xludf.DUMMYFUNCTION("""COMPUTED_VALUE"""),"TAK20 STOP 247") -> TAK20 STOP 247 | N29: =IFERROR(__xludf.DUMMYFUNCTION("""COMPUTED_VALUE"""),"08TM0017") -> 08TM0017 | O29: =IFERROR(__xludf.DUMMYFUNCTION("""COMPUTED_VALUE"""),"Phân bón Vi lượng AGAMA-BATFUNG") -> Phân bón Vi lượng AGAMA-BATFUNG | P29: =IFERROR(__xludf.DUMMYFUNCTION("""COMPUTED_VALUE"""),"#N/A") -> #N/A | Q29: =IFERROR(__xludf.DUMMYFUNCTION("""COMPUTED_VALUE"""),"KHÔNG KHỚP") -> KHÔNG KHỚP
A30: =IFERROR(__xludf.DUMMYFUNCTION("""COMPUTED_VALUE"""),27.0) -> 27 | B30: =IFERROR(__xludf.DUMMYFUNCTION("""COMPUTED_VALUE"""),45892.0) -> 45892 | C30: =IFERROR(__xludf.DUMMYFUNCTION("""COMPUTED_VALUE"""),1.0) -> 1 | D30: =IFERROR(__xludf.DUMMYFUNCTION("""COMPUTED_VALUE"""),"CT MỚI") -> CT MỚI | G30: =IFERROR(__xludf.DUMMYFUNCTION("""COMPUTED_VALUE"""),"HH4006") -> HH4006 | H30: =IFERROR(__xludf.DUMMYFUNCTION("""COMPUTED_VALUE"""),"GC - II - 4006 - CSSX An Khang (A.Dinh) - TAK20 (Bột màu trắng) - 1kg - 20") -> GC - II - 4006 - CSSX An Khang (A.Dinh) - TAK20 (Bột màu trắng) - 1kg - 20 | I30: =IFERROR(__xludf.DUMMYFUNCTION("""COMPUTED_VALUE"""),"#N/A") -> #N/A | L30: =IFERROR(__xludf.DUMMYFUNCTION("""COMPUTED_VALUE"""),"A05200824") -> A05200824 | M30: =IFERROR(__xludf.DUMMYFUNCTION("""COMPUTED_VALUE"""),"TAK20 STOP 247") -> TAK20 STOP 247 | N30: =IFERROR(__xludf.DUMMYFUNCTION("""COMPUTED_VALUE"""),"08TM0017") -> 08TM0017 | O30: =IFERROR(__xludf.DUMMYFUNCTION("""COMPUTED_VALUE"""),"Phân bón Vi lượng AGAMA-BATFUNG") -> Phân bón Vi lượng AGAMA-BATFUNG | P30: =IFERROR(__xludf.DUMMYFUNCTION("""COMPUTED_VALUE"""),"#N/A") -> #N/A | Q30: =IFERROR(__xludf.DUMMYFUNCTION("""COMPUTED_VALUE"""),"KHÔNG KHỚP") -> KHÔNG KHỚP
A31: =IFERROR(__xludf.DUMMYFUNCTION("""COMPUTED_VALUE"""),28.0) -> 28 | B31: =IFERROR(__xludf.DUMMYFUNCTION("""COMPUTED_VALUE"""),45892.0) -> 45892 | C31: =IFERROR(__xludf.DUMMYFUNCTION("""COMPUTED_VALUE"""),1.0) -> 1 | D31: =IFERROR(__xludf.DUMMYFUNCTION("""COMPUTED_VALUE"""),"CT MỚI") -> CT MỚI | G31: =IFERROR(__xludf.DUMMYFUNCTION("""COMPUTED_VALUE"""),"HH3851") -> HH3851 | H31: =IFERROR(__xludf.DUMMYFUNCTION("""COMPUTED_VALUE"""),"GC - IV - 3851 - NHP GROUP - ULTRA KEO CABOR (Nước vàng) - 200ml - 40") -> GC - IV - 3851 - NHP GROUP - ULTRA KEO CABOR (Nước vàng) - 200ml - 40 | I31: =IFERROR(__xludf.DUMMYFUNCTION("""COMPUTED_VALUE"""),"#N/A") -> #N/A | M31: =IFERROR(__xludf.DUMMYFUNCTION("""COMPUTED_VALUE"""),"ULTRA KEO CABOR BOCAX US.BOCAXX") -> ULTRA KEO CABOR BOCAX US.BOCAXX | N31: =IFERROR(__xludf.DUMMYFUNCTION("""COMPUTED_VALUE"""),"10CR0001V1") -> 10CR0001V1 | O31: =IFERROR(__xludf.DUMMYFUNCTION("""COMPUTED_VALUE"""),"Phân bón Vi lượng Run Fast") -> Phân bón Vi lượng Run Fast | P31: =IFERROR(__xludf.DUMMYFUNCTION("""COMPUTED_VALUE"""),"#N/A") -> #N/A | Q31: =IFERROR(__xludf.DUMMYFUNCTION("""COMPUTED_VALUE"""),"KHÔNG KHỚP") -> KHÔNG KHỚP
A32: =IFERROR(__xludf.DUMMYFUNCTION("""COMPUTED_VALUE"""),29.0) -> 29 | B32: =IFERROR(__xludf.DUMMYFUNCTION("""COMPUTED_VALUE"""),45892.0) -> 45892 | C32: =IFERROR(__xludf.DUMMYFUNCTION("""COMPUTED_VALUE"""),1.0) -> 1 | D32: =IFERROR(__xludf.DUMMYFUNCTION("""COMPUTED_VALUE"""),"CT MỚI") -> CT MỚI | G32: =IFERROR(__xludf.DUMMYFUNCTION("""COMPUTED_VALUE"""),"HH3972") -> HH3972 | H32: =IFERROR(__xludf.DUMMYFUNCTION("""COMPUTED_VALUE"""),"GC - IV - 3972 - THÀNH CÔNG AGRI - ULTRA FRUIT (Gel nâu đen) - 20L - 1") -> GC - IV - 3972 - THÀNH CÔNG AGRI - ULTRA FRUIT (Gel nâu đen) - 20L - 1 | I32: =IFERROR(__xludf.DUMMYFUNCTION("""COMPUTED_VALUE"""),"#N/A") -> #N/A | M32: =IFERROR(__xludf.DUMMYFUNCTION("""COMPUTED_VALUE"""),"ULTRA FRUIT") -> ULTRA FRUIT | N32: =IFERROR(__xludf.DUMMYFUNCTION("""COMPUTED_VALUE"""),"11TT0006V1") -> 11TT0006V1 | O32: =IFERROR(__xludf.DUMMYFUNCTION("""COMPUTED_VALUE"""),"Phân bón Vi lượng Quantity New") -> Phân bón Vi lượng Quantity New | P32: =IFERROR(__xludf.DUMMYFUNCTION("""COMPUTED_VALUE"""),"#N/A") -> #N/A | Q32: =IFERROR(__xludf.DUMMYFUNCTION("""COMPUTED_VALUE"""),"KHÔNG KHỚP") -> KHÔNG KHỚP
A33: =IFERROR(__xludf.DUMMYFUNCTION("""COMPUTED_VALUE"""),30.0) -> 30 | B33: =IFERROR(__xludf.DUMMYFUNCTION("""COMPUTED_VALUE"""),45892.0) -> 45892 | C33: =IFERROR(__xludf.DUMMYFUNCTION("""COMPUTED_VALUE"""),1.0) -> 1 | D33: =IFERROR(__xludf.DUMMYFUNCTION("""COMPUTED_VALUE"""),"CT MỚI") -> CT MỚI | G33: =IFERROR(__xludf.DUMMYFUNCTION("""COMPUTED_VALUE"""),"HH3121") -> HH3121 | H33: =IFERROR(__xludf.DUMMYFUNCTION("""COMPUTED_VALUE"""),"GC - IV - 3121 - NHP GROUP - ULTRAKEO ZN+ (Nước trắng sữa) - 200ml - 40") -> GC - IV - 3121 - NHP GROUP - ULTRAKEO ZN+ (Nước trắng sữa) - 200ml - 40 | I33: =IFERROR(__xludf.DUMMYFUNCTION("""COMPUTED_VALUE"""),"#N/A") -> #N/A | L33: =IFERROR(__xludf.DUMMYFUNCTION("""COMPUTED_VALUE"""),"A02211024") -> A02211024 | M33: =IFERROR(__xludf.DUMMYFUNCTION("""COMPUTED_VALUE"""),"ULTRAKEO ZN+") -> ULTRAKEO ZN+ | N33: =IFERROR(__xludf.DUMMYFUNCTION("""COMPUTED_VALUE"""),"13XL0010") -> 13XL0010 | O33: =IFERROR(__xludf.DUMMYFUNCTION("""COMPUTED_VALUE"""),"Phân bón Vi lượng MICKEY") -> Phân bón Vi lượng MICKEY | P33: =IFERROR(__xludf.DUMMYFUNCTION("""COMPUTED_VALUE"""),"#N/A") -> #N/A | Q33: =IFERROR(__xludf.DUMMYFUNCTION("""COMPUTED_VALUE"""),"KHÔNG KHỚP") -> KHÔNG KHỚP
A34: =IFERROR(__xludf.DUMMYFUNCTION("""COMPUTED_VALUE"""),31.0) -> 31 | B34: =IFERROR(__xludf.DUMMYFUNCTION("""COMPUTED_VALUE"""),45892.0) -> 45892 | C34: =IFERROR(__xludf.DUMMYFUNCTION("""COMPUTED_VALUE"""),1.0) -> 1 | D34: =IFERROR(__xludf.DUMMYFUNCTION("""COMPUTED_VALUE"""),"CT MỚI") -> CT MỚI | G34: =IFERROR(__xludf.DUMMYFUNCTION("""COMPUTED_VALUE"""),"HH4005") -> HH4005 | H34: =IFERROR(__xludf.DUMMYFUNCTION("""COMPUTED_VALUE"""),"GC - IV - 4005 - AGRITECH - AGRI NOVA (Nước nâu đen) - 5L - 4") -> GC - IV - 4005 - AGRITECH - AGRI NOVA (Nước nâu đen) - 5L - 4 | I34: =IFERROR(__xludf.DUMMYFUNCTION("""COMPUTED_VALUE"""),"#N/A") -> #N/A | L34: =IFERROR(__xludf.DUMMYFUNCTION("""COMPUTED_VALUE"""),"A01161024") -> A01161024 | M34: =IFERROR(__xludf.DUMMYFUNCTION("""COMPUTED_VALUE"""),"ORGA STRONG AGRI BIO FISH AGRI NOVA") -> ORGA STRONG AGRI BIO FISH AGRI NOVA | N34: =IFERROR(__xludf.DUMMYFUNCTION("""COMPUTED_VALUE"""),"19DD0010V2") -> 19DD0010V2 | O34: =IFERROR(__xludf.DUMMYFUNCTION("""COMPUTED_VALUE"""),"Phân bón Hữu cơ SH Agro Organic Fertilizer 20") -> Phân bón Hữu cơ SH Agro Organic Fertilizer 20 | P34: =IFERROR(__xludf.DUMMYFUNCTION("""COMPUTED_VALUE"""),"#N/A") -> #N/A | Q34: =IFERROR(__xludf.DUMMYFUNCTION("""COMPUTED_VALUE"""),"KHÔNG KHỚP") -> KHÔNG KHỚP
A35: =IFERROR(__xludf.DUMMYFUNCTION("""COMPUTED_VALUE"""),32.0) -> 32 | B35: =IFERROR(__xludf.DUMMYFUNCTION("""COMPUTED_VALUE"""),45897.0) -> 45897 | C35: =IFERROR(__xludf.DUMMYFUNCTION("""COMPUTED_VALUE"""),1.0) -> 1 | D35: =IFERROR(__xludf.DUMMYFUNCTION("""COMPUTED_VALUE"""),"CT MỚI") -> CT MỚI | G35: =IFERROR(__xludf.DUMMYFUNCTION("""COMPUTED_VALUE"""),"HH3903") -> HH3903 | H35: =IFERROR(__xludf.DUMMYFUNCTION("""COMPUTED_VALUE"""),"GC - V - 3903 - N2SBIO - N2 MG ZN-70 (Nước xanh lá) - 500ml - 40") -> GC - V - 3903 - N2SBIO - N2 MG ZN-70 (Nước xanh lá) - 500ml - 40 | I35: =IFERROR(__xludf.DUMMYFUNCTION("""COMPUTED_VALUE"""),"#N/A") -> #N/A | L35: =IFERROR(__xludf.DUMMYFUNCTION("""COMPUTED_VALUE"""),"N01080825") -> N01080825 | M35: =IFERROR(__xludf.DUMMYFUNCTION("""COMPUTED_VALUE"""),"N2 MgZn-52") -> N2 MgZn-52 | N35: =IFERROR(__xludf.DUMMYFUNCTION("""COMPUTED_VALUE"""),"23GS0002") -> 23GS0002 | O35: =IFERROR(__xludf.DUMMYFUNCTION("""COMPUTED_VALUE"""),"Phân bón vi lượng Phú Sĩ FJ-09 Kẽm Mg") -> Phân bón vi lượng Phú Sĩ FJ-09 Kẽm Mg | P35: =IFERROR(__xludf.DUMMYFUNCTION("""COMPUTED_VALUE"""),"#N/A") -> #N/A | Q35: =IFERROR(__xludf.DUMMYFUNCTION("""COMPUTED_VALUE"""),"KHÔNG KHỚP") -> KHÔNG KHỚP
A36: =IFERROR(__xludf.DUMMYFUNCTION("""COMPUTED_VALUE"""),33.0) -> 33 | B36: =IFERROR(__xludf.DUMMYFUNCTION("""COMPUTED_VALUE"""),45897.0) -> 45897 | C36: =IFERROR(__xludf.DUMMYFUNCTION("""COMPUTED_VALUE"""),1.0) -> 1 | D36: =IFERROR(__xludf.DUMMYFUNCTION("""COMPUTED_VALUE"""),"CT MỚI") -> CT MỚI | G36: =IFERROR(__xludf.DUMMYFUNCTION("""COMPUTED_VALUE"""),"HH2899") -> HH2899 | H36: =IFERROR(__xludf.DUMMYFUNCTION("""COMPUTED_VALUE"""),"GC - IV - 2899 - CTY ASAHI NHẬT BẢN - ULTRA BUD (Nước nâu đen) - 22kg - 1") -> GC - IV - 2899 - CTY ASAHI NHẬT BẢN - ULTRA BUD (Nước nâu đen) - 22kg - 1 | I36: =IFERROR(__xludf.DUMMYFUNCTION("""COMPUTED_VALUE"""),"#N/A") -> #N/A | L36: =IFERROR(__xludf.DUMMYFUNCTION("""COMPUTED_VALUE"""),"A06291024") -> A06291024 | M36: =IFERROR(__xludf.DUMMYFUNCTION("""COMPUTED_VALUE"""),"ULTRA BUD") -> ULTRA BUD | N36: =IFERROR(__xludf.DUMMYFUNCTION("""COMPUTED_VALUE"""),"01RR0036V1") -> 01RR0036V1 | O36: =IFERROR(__xludf.DUMMYFUNCTION("""COMPUTED_VALUE"""),"Phân bón Hữu cơ SH Agro Organic Fertilizer 20") -> Phân bón Hữu cơ SH Agro Organic Fertilizer 20 | P36: =IFERROR(__xludf.DUMMYFUNCTION("""COMPUTED_VALUE"""),"#N/A") -> #N/A | Q36: =IFERROR(__xludf.DUMMYFUNCTION("""COMPUTED_VALUE"""),"KHÔNG KHỚP") -> KHÔNG KHỚP
A37: =IFERROR(__xludf.DUMMYFUNCTION("""COMPUTED_VALUE"""),34.0) -> 34 | B37: =IFERROR(__xludf.DUMMYFUNCTION("""COMPUTED_VALUE"""),45891.0) -> 45891 | C37: =IFERROR(__xludf.DUMMYFUNCTION("""COMPUTED_VALUE"""),1.0) -> 1 | D37: =IFERROR(__xludf.DUMMYFUNCTION("""COMPUTED_VALUE"""),"CT MỚI") -> CT MỚI | G37: =IFERROR(__xludf.DUMMYFUNCTION("""COMPUTED_VALUE"""),"HH3912") -> HH3912 | H37: =IFERROR(__xludf.DUMMYFUNCTION("""COMPUTED_VALUE"""),"GC - IV - 3912 - Cty Hóa Nông Shino - SHINO MIX (Nước xanh lơ) - 50ml - 300") -> GC - IV - 3912 - Cty Hóa Nông Shino - SHINO MIX (Nước xanh lơ) - 50ml - 300 | I37: =IFERROR(__xludf.DUMMYFUNCTION("""COMPUTED_VALUE"""),"#N/A") -> #N/A | L37: =IFERROR(__xludf.DUMMYFUNCTION("""COMPUTED_VALUE"""),"A07290725") -> A07290725 | M37: =IFERROR(__xludf.DUMMYFUNCTION("""COMPUTED_VALUE"""),"SHINOMIX -02") -> SHINOMIX -02 | N37: =IFERROR(__xludf.DUMMYFUNCTION("""COMPUTED_VALUE"""),"01RR0070") -> 01RR0070 | O37: =IFERROR(__xludf.DUMMYFUNCTION("""COMPUTED_VALUE"""),"Phân bón lá NPK-Vi lượng GNC 19") -> Phân bón lá NPK-Vi lượng GNC 19 | P37: =IFERROR(__xludf.DUMMYFUNCTION("""COMPUTED_VALUE"""),"#N/A") -> #N/A | Q37: =IFERROR(__xludf.DUMMYFUNCTION("""COMPUTED_VALUE"""),"KHÔNG KHỚP") -> KHÔNG KHỚP
A38: =IFERROR(__xludf.DUMMYFUNCTION("""COMPUTED_VALUE"""),35.0) -> 35 | B38: =IFERROR(__xludf.DUMMYFUNCTION("""COMPUTED_VALUE"""),45897.0) -> 45897 | C38: =IFERROR(__xludf.DUMMYFUNCTION("""COMPUTED_VALUE"""),1.0) -> 1 | D38: =IFERROR(__xludf.DUMMYFUNCTION("""COMPUTED_VALUE"""),"CT MỚI") -> CT MỚI | G38: =IFERROR(__xludf.DUMMYFUNCTION("""COMPUTED_VALUE"""),"HH3967") -> HH3967 | H38: =IFERROR(__xludf.DUMMYFUNCTION("""COMPUTED_VALUE"""),"BAMBOO - VI - 3967 - BAMBOO 10.10.20 TE (chưa xác định) - 500ml - 40") -> BAMBOO - VI - 3967 - BAMBOO 10.10.20 TE (chưa xác định) - 500ml - 40 | I38: =IFERROR(__xludf.DUMMYFUNCTION("""COMPUTED_VALUE"""),"#N/A") -> #N/A | L38: =IFERROR(__xludf.DUMMYFUNCTION("""COMPUTED_VALUE"""),"BB28040725") -> BB28040725 | M38: =IFERROR(__xludf.DUMMYFUNCTION("""COMPUTED_VALUE"""),"BB 10 - 10 - 20 TE") -> BB 10 - 10 - 20 TE | N38: =IFERROR(__xludf.DUMMYFUNCTION("""COMPUTED_VALUE"""),"04VG0038") -> 04VG0038 | O38: =IFERROR(__xludf.DUMMYFUNCTION("""COMPUTED_VALUE"""),"Phân bón hỗn hợp NPK GNC 102") -> Phân bón hỗn hợp NPK GNC 102 | P38: =IFERROR(__xludf.DUMMYFUNCTION("""COMPUTED_VALUE"""),"#N/A") -> #N/A | Q38: =IFERROR(__xludf.DUMMYFUNCTION("""COMPUTED_VALUE"""),"KHÔNG KHỚP") -> KHÔNG KHỚP
A39: =IFERROR(__xludf.DUMMYFUNCTION("""COMPUTED_VALUE"""),36.0) -> 36 | B39: =IFERROR(__xludf.DUMMYFUNCTION("""COMPUTED_VALUE"""),45892.0) -> 45892 | C39: =IFERROR(__xludf.DUMMYFUNCTION("""COMPUTED_VALUE"""),1.0) -> 1 | D39: =IFERROR(__xludf.DUMMYFUNCTION("""COMPUTED_VALUE"""),"CT MỚI") -> CT MỚI | G39: =IFERROR(__xludf.DUMMYFUNCTION("""COMPUTED_VALUE"""),"HH3926") -> HH3926 | H39: =IFERROR(__xludf.DUMMYFUNCTION("""COMPUTED_VALUE"""),"GC - IV - 3926 - Cty Newtex - KẼM XANH T5 (Dạng SC Xanh dương) - 500ml - 40") -> GC - IV - 3926 - Cty Newtex - KẼM XANH T5 (Dạng SC Xanh dương) - 500ml - 40 | I39: =IFERROR(__xludf.DUMMYFUNCTION("""COMPUTED_VALUE"""),"#N/A") -> #N/A | L39: =IFERROR(__xludf.DUMMYFUNCTION("""COMPUTED_VALUE"""),"A06200825") -> A06200825 | M39: =IFERROR(__xludf.DUMMYFUNCTION("""COMPUTED_VALUE"""),"AMINO MAGIE KẼM CAO CẤP 01") -> AMINO MAGIE KẼM CAO CẤP 01 | N39: =IFERROR(__xludf.DUMMYFUNCTION("""COMPUTED_VALUE"""),"23GS0010") -> 23GS0010 | O39: =IFERROR(__xludf.DUMMYFUNCTION("""COMPUTED_VALUE"""),"Phân bón vi lượng Phú Sĩ FJ-09 Kẽm Mg") -> Phân bón vi lượng Phú Sĩ FJ-09 Kẽm Mg | P39: =IFERROR(__xludf.DUMMYFUNCTION("""COMPUTED_VALUE"""),"#N/A") -> #N/A | Q39: =IFERROR(__xludf.DUMMYFUNCTION("""COMPUTED_VALUE"""),"KHÔNG KHỚP") -> KHÔNG KHỚP
A40: =IFERROR(__xludf.DUMMYFUNCTION("""COMPUTED_VALUE"""),37.0) -> 37 | B40: =IFERROR(__xludf.DUMMYFUNCTION("""COMPUTED_VALUE"""),45892.0) -> 45892 | C40: =IFERROR(__xludf.DUMMYFUNCTION("""COMPUTED_VALUE"""),1.0) -> 1 | D40: =IFERROR(__xludf.DUMMYFUNCTION("""COMPUTED_VALUE"""),"CT MỚI") -> CT MỚI | G40: =IFERROR(__xludf.DUMMYFUNCTION("""COMPUTED_VALUE"""),"HH4010") -> HH4010 | H40: =IFERROR(__xludf.DUMMYFUNCTION("""COMPUTED_VALUE"""),"GC - IV - 4010 - AGRITECH HÀ LAN - Phân bón hữu cơ AGRITECH HL CANXI BOZN (Dạng SC - Xanh dương) - 500ml - 40") -> GC - IV - 4010 - AGRITECH HÀ LAN - Phân bón hữu cơ AGRITECH HL CANXI BOZN (Dạng SC - Xanh dương) - 500ml - 40 | I40: =IFERROR(__xludf.DUMMYFUNCTION("""COMPUTED_VALUE"""),"#N/A") -> #N/A | L40: =IFERROR(__xludf.DUMMYFUNCTION("""COMPUTED_VALUE"""),"A01140725") -> A01140725 | M40: =IFERROR(__xludf.DUMMYFUNCTION("""COMPUTED_VALUE"""),"Canxibo Agritech Hà Lan") -> Canxibo Agritech Hà Lan | N40: =IFERROR(__xludf.DUMMYFUNCTION("""COMPUTED_VALUE"""),"10CR0025V2") -> 10CR0025V2 | O40: =IFERROR(__xludf.DUMMYFUNCTION("""COMPUTED_VALUE"""),"Phân bón Hữu cơ AGRITECH HL CANXI BOZN") -> Phân bón Hữu cơ AGRITECH HL CANXI BOZN | P40: =IFERROR(__xludf.DUMMYFUNCTION("""COMPUTED_VALUE"""),"#N/A") -> #N/A | Q40: =IFERROR(__xludf.DUMMYFUNCTION("""COMPUTED_VALUE"""),"KHÔNG KHỚP") -> KHÔNG KHỚP
A41: =IFERROR(__xludf.DUMMYFUNCTION("""COMPUTED_VALUE"""),38.0) -> 38 | B41: =IFERROR(__xludf.DUMMYFUNCTION("""COMPUTED_VALUE"""),45894.0) -> 45894 | C41: =IFERROR(__xludf.DUMMYFUNCTION("""COMPUTED_VALUE"""),1.0) -> 1 | D41: =IFERROR(__xludf.DUMMYFUNCTION("""COMPUTED_VALUE"""),"CT MỚI") -> CT MỚI | G41: =IFERROR(__xludf.DUMMYFUNCTION("""COMPUTED_VALUE"""),"HH3031") -> HH3031 | H41: =IFERROR(__xludf.DUMMYFUNCTION("""COMPUTED_VALUE"""),"GC - IV - 3031 - AGRITECH - NUTI ROOTS 2 USA - 10kg - 1") -> GC - IV - 3031 - AGRITECH - NUTI ROOTS 2 USA - 10kg - 1 | I41: =IFERROR(__xludf.DUMMYFUNCTION("""COMPUTED_VALUE"""),"#N/A") -> #N/A | L41: =IFERROR(__xludf.DUMMYFUNCTION("""COMPUTED_VALUE"""),"A05101224") -> A05101224 | M41: =IFERROR(__xludf.DUMMYFUNCTION("""COMPUTED_VALUE"""),"NUTI ROOTS 2 USA") -> NUTI ROOTS 2 USA | N41: =IFERROR(__xludf.DUMMYFUNCTION("""COMPUTED_VALUE"""),"01RR0059V1") -> 01RR0059V1 | O41: =IFERROR(__xludf.DUMMYFUNCTION("""COMPUTED_VALUE"""),"Phân bón Hữu cơ sinh học Nam Kinh 02") -> Phân bón Hữu cơ sinh học Nam Kinh 02 | P41: =IFERROR(__xludf.DUMMYFUNCTION("""COMPUTED_VALUE"""),"#N/A") -> #N/A | Q41: =IFERROR(__xludf.DUMMYFUNCTION("""COMPUTED_VALUE"""),"KHÔNG KHỚP") -> KHÔNG KHỚP
...

Sheet 2. HÀNG NGÀY 2026
A2: STT | B2: NCC đề xuất | C2: Mã đơn đặt hàng (po) | D2: Ngày yêu cầu | E2: Trạng thái kiểm duyệt nhãn | F2: Thương hiệu | G2: Mã Hàng | H2: Tên hàng | I2: Phân loại | J2: Tên pháp lý | K2: Công thức | L2: Màu btp | M2: ĐVT | N2: Quy cách thùng | O2: SLTP/Thùng | P2: Sl thành phẩm (gồm khuyến mãi) | Q2: Ngày yêu cầu sẵn kho NCC | R2: CÔNG THỨC GẦN NHẤT (Tham Khảo) | S2: Ngày check giá | T2: Ghi chú | U2: Công thức BĐM từ lab | V2: Ngày cập nhật | W2: Ghi chú Nhật Anh
A3: =COUNTIF($S$3:S3,S3) -> 1 | B3: Dego Cần Thơ | C3: ATP06012607 | D3: 46028 | E3: Đã duyệt | F3: ABA | G3: HH4545 | H3: GC - V - 4545 - GNH - DR. PHOENIX SUPER ĐỒNG (Nước xanh nõn chuối) - 100ml - 100 | I3: Phân bón | J3: Vi lượng Agama - Cu | K3: A01311025 | L3: Nước xanh nõn chuối | M3: Chai | N3: 100 | O3: 10 | P3: 1000 | Q3: 46039 | R3: 17KN0011 | S3: 46028 | T3: Chưa có công thức lab | U3: {=IFERROR(index('3. Công thức lab theo từng mã h'!J:J,MATCH(C3,'3. Công thức lab theo từng mã h'!L:L,0)),"")}
A4: =COUNTIF($S$3:S4,S4) -> 2 | B4: Dego Cần Thơ | C4: ATP06012608 | D4: 46028 | E4: Đã duyệt | F4: ABA | G4: HH4546 | H4: GC - V - 4546 - GNH - DR. PHOENIX SUPER ĐỒNG (Nước xanh nõn chuối) - 250ml - 40 | I4: Phân bón | J4: Vi lượng Agama - Cu | K4: A01311025 | L4: Nước xanh nõn chuối | M4: Chai | N4: 40 | O4: 10 | P4: 400 | Q4: 46039 | R4: 17KN0011 | S4: 46028 | T4: Chưa có công thức lab | U4: {=IFERROR(index('3. Công thức lab theo từng mã h'!J:J,MATCH(C4,'3. Công thức lab theo từng mã h'!L:L,0)),"")}
A5: =COUNTIF($S$3:S5,S5) -> 1 | B5: Dego Cần Thơ | C5: ATP08012603 | D5: 46030 | E5: Đã duyệt | F5: ABA | G5: HH4608 | H5: GC - V - 4608 - CTY ASAHI NHẬT BẢN - RONBIN SAMURAI (Gel nâu đen) - 500ml - 40 | I5: Phân bón | J5: Vi lượng Quantity New | K5: A04270225 | L5: Gel nâu đen | M5: Chai | N5: 40 | O5: 20 | P5: 800 | Q5: 46039 | R5: 13XL0008V2 | S5: 46030 | T5: Chưa có công thức lab | U5: {=IFERROR(index('3. Công thức lab theo từng mã h'!J:J,MATCH(C5,'3. Công thức lab theo từng mã h'!L:L,0)),"")}
A6: =COUNTIF($S$3:S6,S6) -> 2 | B6: Dego Cần Thơ | C6: ITP08012608 | D6: 46030 | F6: IDA | G6: HH3050 | H6: IDA Global - I - 3050 - SIÊU KẼM 247 (Nước vàng nhạt) - 250ml - 40 | I6: Phân bón | J6: Vi lượng AGAMA-ZN | K6: Đóng theo đơn gần nhất | L6: Nước vàng nhạt | M6: Chai | N6: 40 | O6: 10 | P6: 400 | Q6: 46037 | R6: 03DD0003 | S6: 46030 | T6: Chưa có công thức lab | U6: {=IFERROR(index('3. Công thức lab theo từng mã h'!J:J,MATCH(C6,'3. Công thức lab theo từng mã h'!L:L,0)),"")}
A7: =COUNTIF($S$3:S7,S7) -> 3 | B7: Dego Cần Thơ | C7: ITP08012613 | D7: 46030 | F7: IDA | G7: HH4609 | H7: IDA GLOBAL (ĐL ÚT TÈO) - Hữu Cơ Organic ĐGP 01 - WINNER EXTRA - 500ml - 40 | I7: Phân bón | J7: Hữu Cơ Organic ĐGP 01 | K7: Công thức lab I01171025 | L7: Nước nâu đen | M7: Chai | N7: 40 | O7: 25 | P7: 1000 | Q7: 46050 | R7: 04VG0010V3 | S7: 46030 | T7: Chưa có công thức lab | U7: {=IFERROR(index('3. Công thức lab theo từng mã h'!J:J,MATCH(C7,'3. Công thức lab theo từng mã h'!L:L,0)),"")}
A8: =COUNTIF($S$3:S8,S8) -> 1 | B8: Dego Cần Thơ | C8: XTP.09012601 | D8: 46031 | F8: Dr.xanh | G8: HH4204 | H8: DR.XANH - VIII - 4204 - ROBUST EXTRA (Gel nâu đen) - 500ml - 40 | J8: Root US90 | K8: X01180825 | L8: Đen | M8: chai | N8: 40 | O8: 75 | P8: 3000 | Q8: 46042 | R8: 01RR0071V1 | S8: 46031 | T8: Chưa có công thức lab | U8: {=IFERROR(index('3. Công thức lab theo từng mã h'!J:J,MATCH(C8,'3. Công thức lab theo từng mã h'!L:L,0)),"")}
A9: =COUNTIF($S$3:S9,S9) -> 2 | B9: Dego Cần Thơ | C9: XTP.09012602 | D9: 46031 | F9: Dr.xanh | G9: HH4206 | H9: DR.XANH - VIII - 4206 - ROBUST EXTRA (Gel nâu đen) - 250ml - 40 | J9: Root US90 | K9: X01180825 | L9: Đen | M9: chai | N9: 40 | O9: 50 | P9: 2000 | Q9: 46042 | R9: 01RR0071V5 | S9: 46031 | T9: Chưa có công thức lab | U9: {=IFERROR(index('3. Công thức lab theo từng mã h'!J:J,MATCH(C9,'3. Công thức lab theo từng mã h'!L:L,0)),"")}
A10: =COUNTIF($S$3:S10,S10) -> 0 | B10: Dego Cần Thơ | C10: ATP16042602 | D10: 46128 | E10: Đã duyệt | F10: ABA | G10: HH4479 | H10: GC - V - 4479 - CTY QUANG ĐĂNG AGRICULTURE (ĐL ÚT TIỆP) - COMBI GREEN (Nước trắng sữa) - 250ml - 40 | I10: Phân bón | J10: vi lượng Phú Sĩ FJ-09 Kẽm Mg | K10: A02011025 | L10: Nước trắng sữa | M10: Chai | N10: 40 | O10: 10 | P10: 400 | Q10: 46137 | U10: {=IFERROR(index('3. Công thức lab theo từng mã h'!J:J,MATCH(C10,'3. Công thức lab theo từng mã h'!L:L,0)),"")}
A11: =COUNTIF($S$3:S11,S11) -> 0 | B11: Dego Cần Thơ | C11: ATP05052604 | D11: 46147 | E11: Đã duyệt | F11: ABA | G11: HH4976 | H11: GC - V - 4976 - CTY AN LẠC - GROW 7-7-7 + TE (Gel xanh lơ) - 50ml - 300 | I11: Phân bón | J11: lá NPK-vi lượng GNC19 | K11: A07290725 | L11: Gel xanh lơ | M11: Túi/Gói | N11: 300 | O11: 15 | P11: 4500 | Q11: 46158 | R11: 01RR0070 | T11: Có công thức | U11: 01RR0070 | V11: 46147
A12: =COUNTIF($S$3:S12,S12) -> 0 | U12: {=IFERROR(index('3. Công thức lab theo từng mã h'!J:J,MATCH(C12,'3. Công thức lab theo từng mã h'!L:L,0)),"")}
A13: =COUNTIF($S$3:S13,S13) -> 0 | U13: {=IFERROR(index('3. Công thức lab theo từng mã h'!J:J,MATCH(C13,'3. Công thức lab theo từng mã h'!L:L,0)),"")}
A14: =COUNTIF($S$3:S14,S14) -> 0 | U14: {=IFERROR(index('3. Công thức lab theo từng mã h'!J:J,MATCH(C14,'3. Công thức lab theo từng mã h'!L:L,0)),"")}
A15: =COUNTIF($S$3:S15,S15) -> 0 | U15: {=IFERROR(index('3. Công thức lab theo từng mã h'!J:J,MATCH(C15,'3. Công thức lab theo từng mã h'!L:L,0)),"")}
